/var/www/bookscot/public_site/debug.logInternal Server Error: /directory/37/
Traceback (most recent call last):
  File "/home/bookofscotland/miniconda3/envs/BOS/lib/python3.8/site-packages/django/db/backends/utils.py", line 89, in _execute
    return self.cursor.execute(sql, params)
  File "/home/bookofscotland/miniconda3/envs/BOS/lib/python3.8/site-packages/django/db/backends/mysql/base.py", line 75, in execute
    return self.cursor.execute(query, args)
  File "/home/bookofscotland/miniconda3/envs/BOS/lib/python3.8/site-packages/MySQLdb/cursors.py", line 179, in execute
    res = self._query(mogrified_query)
  File "/home/bookofscotland/miniconda3/envs/BOS/lib/python3.8/site-packages/MySQLdb/cursors.py", line 330, in _query
    db.query(q)
  File "/home/bookofscotland/miniconda3/envs/BOS/lib/python3.8/site-packages/MySQLdb/connections.py", line 261, in query
    _mysql.connection.query(self, query)
MySQLdb.ProgrammingError: (1146, "Table 'aibos_django.bookscot_site_directory' doesn't exist")

The above exception was the direct cause of the following exception:

Traceback (most recent call last):
  File "/home/bookofscotland/miniconda3/envs/BOS/lib/python3.8/site-packages/asgiref/sync.py", line 534, in thread_handler
    raise exc_info[1]
  File "/home/bookofscotland/miniconda3/envs/BOS/lib/python3.8/site-packages/django/core/handlers/exception.py", line 42, in inner
    response = await get_response(request)
  File "/home/bookofscotland/miniconda3/envs/BOS/lib/python3.8/site-packages/django/core/handlers/base.py", line 253, in _get_response_async
    response = await wrapped_callback(
  File "/home/bookofscotland/miniconda3/envs/BOS/lib/python3.8/site-packages/asgiref/sync.py", line 479, in __call__
    ret: _R = await loop.run_in_executor(
  File "/home/bookofscotland/miniconda3/envs/BOS/lib/python3.8/concurrent/futures/thread.py", line 57, in run
    result = self.fn(*self.args, **self.kwargs)
  File "/home/bookofscotland/miniconda3/envs/BOS/lib/python3.8/site-packages/asgiref/sync.py", line 538, in thread_handler
    return func(*args, **kwargs)
  File "/var/www/bookscot/public_site/views.py", line 70, in directory_main_view
    directory = get_object_or_404(Directory, id=directory_id)
  File "/home/bookofscotland/miniconda3/envs/BOS/lib/python3.8/site-packages/django/shortcuts.py", line 85, in get_object_or_404
    return queryset.get(*args, **kwargs)
  File "/home/bookofscotland/miniconda3/envs/BOS/lib/python3.8/site-packages/django/db/models/query.py", line 646, in get
    num = len(clone)
  File "/home/bookofscotland/miniconda3/envs/BOS/lib/python3.8/site-packages/django/db/models/query.py", line 376, in __len__
    self._fetch_all()
  File "/home/bookofscotland/miniconda3/envs/BOS/lib/python3.8/site-packages/django/db/models/query.py", line 1866, in _fetch_all
    self._result_cache = list(self._iterable_class(self))
  File "/home/bookofscotland/miniconda3/envs/BOS/lib/python3.8/site-packages/django/db/models/query.py", line 87, in __iter__
    results = compiler.execute_sql(
  File "/home/bookofscotland/miniconda3/envs/BOS/lib/python3.8/site-packages/django/db/models/sql/compiler.py", line 1395, in execute_sql
    cursor.execute(sql, params)
  File "/home/bookofscotland/miniconda3/envs/BOS/lib/python3.8/site-packages/django/db/backends/utils.py", line 67, in execute
    return self._execute_with_wrappers(
  File "/home/bookofscotland/miniconda3/envs/BOS/lib/python3.8/site-packages/django/db/backends/utils.py", line 80, in _execute_with_wrappers
    return executor(sql, params, many, context)
  File "/home/bookofscotland/miniconda3/envs/BOS/lib/python3.8/site-packages/django/db/backends/utils.py", line 89, in _execute
    return self.cursor.execute(sql, params)
  File "/home/bookofscotland/miniconda3/envs/BOS/lib/python3.8/site-packages/django/db/utils.py", line 91, in __exit__
    raise dj_exc_value.with_traceback(traceback) from exc_value
  File "/home/bookofscotland/miniconda3/envs/BOS/lib/python3.8/site-packages/django/db/backends/utils.py", line 89, in _execute
    return self.cursor.execute(sql, params)
  File "/home/bookofscotland/miniconda3/envs/BOS/lib/python3.8/site-packages/django/db/backends/mysql/base.py", line 75, in execute
    return self.cursor.execute(query, args)
  File "/home/bookofscotland/miniconda3/envs/BOS/lib/python3.8/site-packages/MySQLdb/cursors.py", line 179, in execute
    res = self._query(mogrified_query)
  File "/home/bookofscotland/miniconda3/envs/BOS/lib/python3.8/site-packages/MySQLdb/cursors.py", line 330, in _query
    db.query(q)
  File "/home/bookofscotland/miniconda3/envs/BOS/lib/python3.8/site-packages/MySQLdb/connections.py", line 261, in query
    _mysql.connection.query(self, query)
django.db.utils.ProgrammingError: (1146, "Table 'aibos_django.bookscot_site_directory' doesn't exist")
Internal Server Error: /directory/7/
Traceback (most recent call last):
  File "/home/bookofscotland/miniconda3/envs/BOS/lib/python3.8/site-packages/django/db/backends/utils.py", line 89, in _execute
    return self.cursor.execute(sql, params)
  File "/home/bookofscotland/miniconda3/envs/BOS/lib/python3.8/site-packages/django/db/backends/mysql/base.py", line 75, in execute
    return self.cursor.execute(query, args)
  File "/home/bookofscotland/miniconda3/envs/BOS/lib/python3.8/site-packages/MySQLdb/cursors.py", line 179, in execute
    res = self._query(mogrified_query)
  File "/home/bookofscotland/miniconda3/envs/BOS/lib/python3.8/site-packages/MySQLdb/cursors.py", line 330, in _query
    db.query(q)
  File "/home/bookofscotland/miniconda3/envs/BOS/lib/python3.8/site-packages/MySQLdb/connections.py", line 261, in query
    _mysql.connection.query(self, query)
MySQLdb.ProgrammingError: (1146, "Table 'aibos_django.bookscot_site_directory' doesn't exist")

The above exception was the direct cause of the following exception:

Traceback (most recent call last):
  File "/home/bookofscotland/miniconda3/envs/BOS/lib/python3.8/site-packages/asgiref/sync.py", line 534, in thread_handler
    raise exc_info[1]
  File "/home/bookofscotland/miniconda3/envs/BOS/lib/python3.8/site-packages/django/core/handlers/exception.py", line 42, in inner
    response = await get_response(request)
  File "/home/bookofscotland/miniconda3/envs/BOS/lib/python3.8/site-packages/django/core/handlers/base.py", line 253, in _get_response_async
    response = await wrapped_callback(
  File "/home/bookofscotland/miniconda3/envs/BOS/lib/python3.8/site-packages/asgiref/sync.py", line 479, in __call__
    ret: _R = await loop.run_in_executor(
  File "/home/bookofscotland/miniconda3/envs/BOS/lib/python3.8/concurrent/futures/thread.py", line 57, in run
    result = self.fn(*self.args, **self.kwargs)
  File "/home/bookofscotland/miniconda3/envs/BOS/lib/python3.8/site-packages/asgiref/sync.py", line 538, in thread_handler
    return func(*args, **kwargs)
  File "/var/www/bookscot/public_site/views.py", line 70, in directory_main_view
    directory = get_object_or_404(Directory, id=directory_id)
  File "/home/bookofscotland/miniconda3/envs/BOS/lib/python3.8/site-packages/django/shortcuts.py", line 85, in get_object_or_404
    return queryset.get(*args, **kwargs)
  File "/home/bookofscotland/miniconda3/envs/BOS/lib/python3.8/site-packages/django/db/models/query.py", line 646, in get
    num = len(clone)
  File "/home/bookofscotland/miniconda3/envs/BOS/lib/python3.8/site-packages/django/db/models/query.py", line 376, in __len__
    self._fetch_all()
  File "/home/bookofscotland/miniconda3/envs/BOS/lib/python3.8/site-packages/django/db/models/query.py", line 1866, in _fetch_all
    self._result_cache = list(self._iterable_class(self))
  File "/home/bookofscotland/miniconda3/envs/BOS/lib/python3.8/site-packages/django/db/models/query.py", line 87, in __iter__
    results = compiler.execute_sql(
  File "/home/bookofscotland/miniconda3/envs/BOS/lib/python3.8/site-packages/django/db/models/sql/compiler.py", line 1395, in execute_sql
    cursor.execute(sql, params)
  File "/home/bookofscotland/miniconda3/envs/BOS/lib/python3.8/site-packages/django/db/backends/utils.py", line 67, in execute
    return self._execute_with_wrappers(
  File "/home/bookofscotland/miniconda3/envs/BOS/lib/python3.8/site-packages/django/db/backends/utils.py", line 80, in _execute_with_wrappers
    return executor(sql, params, many, context)
  File "/home/bookofscotland/miniconda3/envs/BOS/lib/python3.8/site-packages/django/db/backends/utils.py", line 89, in _execute
    return self.cursor.execute(sql, params)
  File "/home/bookofscotland/miniconda3/envs/BOS/lib/python3.8/site-packages/django/db/utils.py", line 91, in __exit__
    raise dj_exc_value.with_traceback(traceback) from exc_value
  File "/home/bookofscotland/miniconda3/envs/BOS/lib/python3.8/site-packages/django/db/backends/utils.py", line 89, in _execute
    return self.cursor.execute(sql, params)
  File "/home/bookofscotland/miniconda3/envs/BOS/lib/python3.8/site-packages/django/db/backends/mysql/base.py", line 75, in execute
    return self.cursor.execute(query, args)
  File "/home/bookofscotland/miniconda3/envs/BOS/lib/python3.8/site-packages/MySQLdb/cursors.py", line 179, in execute
    res = self._query(mogrified_query)
  File "/home/bookofscotland/miniconda3/envs/BOS/lib/python3.8/site-packages/MySQLdb/cursors.py", line 330, in _query
    db.query(q)
  File "/home/bookofscotland/miniconda3/envs/BOS/lib/python3.8/site-packages/MySQLdb/connections.py", line 261, in query
    _mysql.connection.query(self, query)
django.db.utils.ProgrammingError: (1146, "Table 'aibos_django.bookscot_site_directory' doesn't exist")
Internal Server Error: /directory/5/
Traceback (most recent call last):
  File "/home/bookofscotland/miniconda3/envs/BOS/lib/python3.8/site-packages/django/db/backends/utils.py", line 89, in _execute
    return self.cursor.execute(sql, params)
  File "/home/bookofscotland/miniconda3/envs/BOS/lib/python3.8/site-packages/django/db/backends/mysql/base.py", line 75, in execute
    return self.cursor.execute(query, args)
  File "/home/bookofscotland/miniconda3/envs/BOS/lib/python3.8/site-packages/MySQLdb/cursors.py", line 179, in execute
    res = self._query(mogrified_query)
  File "/home/bookofscotland/miniconda3/envs/BOS/lib/python3.8/site-packages/MySQLdb/cursors.py", line 330, in _query
    db.query(q)
  File "/home/bookofscotland/miniconda3/envs/BOS/lib/python3.8/site-packages/MySQLdb/connections.py", line 261, in query
    _mysql.connection.query(self, query)
MySQLdb.ProgrammingError: (1146, "Table 'aibos_django.bookscot_site_directory' doesn't exist")

The above exception was the direct cause of the following exception:

Traceback (most recent call last):
  File "/home/bookofscotland/miniconda3/envs/BOS/lib/python3.8/site-packages/asgiref/sync.py", line 534, in thread_handler
    raise exc_info[1]
  File "/home/bookofscotland/miniconda3/envs/BOS/lib/python3.8/site-packages/django/core/handlers/exception.py", line 42, in inner
    response = await get_response(request)
  File "/home/bookofscotland/miniconda3/envs/BOS/lib/python3.8/site-packages/django/core/handlers/base.py", line 253, in _get_response_async
    response = await wrapped_callback(
  File "/home/bookofscotland/miniconda3/envs/BOS/lib/python3.8/site-packages/asgiref/sync.py", line 479, in __call__
    ret: _R = await loop.run_in_executor(
  File "/home/bookofscotland/miniconda3/envs/BOS/lib/python3.8/concurrent/futures/thread.py", line 57, in run
    result = self.fn(*self.args, **self.kwargs)
  File "/home/bookofscotland/miniconda3/envs/BOS/lib/python3.8/site-packages/asgiref/sync.py", line 538, in thread_handler
    return func(*args, **kwargs)
  File "/var/www/bookscot/public_site/views.py", line 70, in directory_main_view
    directory = get_object_or_404(Directory, id=directory_id)
  File "/home/bookofscotland/miniconda3/envs/BOS/lib/python3.8/site-packages/django/shortcuts.py", line 85, in get_object_or_404
    return queryset.get(*args, **kwargs)
  File "/home/bookofscotland/miniconda3/envs/BOS/lib/python3.8/site-packages/django/db/models/query.py", line 646, in get
    num = len(clone)
  File "/home/bookofscotland/miniconda3/envs/BOS/lib/python3.8/site-packages/django/db/models/query.py", line 376, in __len__
    self._fetch_all()
  File "/home/bookofscotland/miniconda3/envs/BOS/lib/python3.8/site-packages/django/db/models/query.py", line 1866, in _fetch_all
    self._result_cache = list(self._iterable_class(self))
  File "/home/bookofscotland/miniconda3/envs/BOS/lib/python3.8/site-packages/django/db/models/query.py", line 87, in __iter__
    results = compiler.execute_sql(
  File "/home/bookofscotland/miniconda3/envs/BOS/lib/python3.8/site-packages/django/db/models/sql/compiler.py", line 1395, in execute_sql
    cursor.execute(sql, params)
  File "/home/bookofscotland/miniconda3/envs/BOS/lib/python3.8/site-packages/django/db/backends/utils.py", line 67, in execute
    return self._execute_with_wrappers(
  File "/home/bookofscotland/miniconda3/envs/BOS/lib/python3.8/site-packages/django/db/backends/utils.py", line 80, in _execute_with_wrappers
    return executor(sql, params, many, context)
  File "/home/bookofscotland/miniconda3/envs/BOS/lib/python3.8/site-packages/django/db/backends/utils.py", line 89, in _execute
    return self.cursor.execute(sql, params)
  File "/home/bookofscotland/miniconda3/envs/BOS/lib/python3.8/site-packages/django/db/utils.py", line 91, in __exit__
    raise dj_exc_value.with_traceback(traceback) from exc_value
  File "/home/bookofscotland/miniconda3/envs/BOS/lib/python3.8/site-packages/django/db/backends/utils.py", line 89, in _execute
    return self.cursor.execute(sql, params)
  File "/home/bookofscotland/miniconda3/envs/BOS/lib/python3.8/site-packages/django/db/backends/mysql/base.py", line 75, in execute
    return self.cursor.execute(query, args)
  File "/home/bookofscotland/miniconda3/envs/BOS/lib/python3.8/site-packages/MySQLdb/cursors.py", line 179, in execute
    res = self._query(mogrified_query)
  File "/home/bookofscotland/miniconda3/envs/BOS/lib/python3.8/site-packages/MySQLdb/cursors.py", line 330, in _query
    db.query(q)
  File "/home/bookofscotland/miniconda3/envs/BOS/lib/python3.8/site-packages/MySQLdb/connections.py", line 261, in query
    _mysql.connection.query(self, query)
django.db.utils.ProgrammingError: (1146, "Table 'aibos_django.bookscot_site_directory' doesn't exist")
Internal Server Error: /directory/13/
Traceback (most recent call last):
  File "/home/bookofscotland/miniconda3/envs/BOS/lib/python3.8/site-packages/django/db/backends/utils.py", line 89, in _execute
    return self.cursor.execute(sql, params)
  File "/home/bookofscotland/miniconda3/envs/BOS/lib/python3.8/site-packages/django/db/backends/mysql/base.py", line 75, in execute
    return self.cursor.execute(query, args)
  File "/home/bookofscotland/miniconda3/envs/BOS/lib/python3.8/site-packages/MySQLdb/cursors.py", line 179, in execute
    res = self._query(mogrified_query)
  File "/home/bookofscotland/miniconda3/envs/BOS/lib/python3.8/site-packages/MySQLdb/cursors.py", line 330, in _query
    db.query(q)
  File "/home/bookofscotland/miniconda3/envs/BOS/lib/python3.8/site-packages/MySQLdb/connections.py", line 261, in query
    _mysql.connection.query(self, query)
MySQLdb.ProgrammingError: (1146, "Table 'aibos_django.bookscot_site_directory' doesn't exist")

The above exception was the direct cause of the following exception:

Traceback (most recent call last):
  File "/home/bookofscotland/miniconda3/envs/BOS/lib/python3.8/site-packages/asgiref/sync.py", line 534, in thread_handler
    raise exc_info[1]
  File "/home/bookofscotland/miniconda3/envs/BOS/lib/python3.8/site-packages/django/core/handlers/exception.py", line 42, in inner
    response = await get_response(request)
  File "/home/bookofscotland/miniconda3/envs/BOS/lib/python3.8/site-packages/django/core/handlers/base.py", line 253, in _get_response_async
    response = await wrapped_callback(
  File "/home/bookofscotland/miniconda3/envs/BOS/lib/python3.8/site-packages/asgiref/sync.py", line 479, in __call__
    ret: _R = await loop.run_in_executor(
  File "/home/bookofscotland/miniconda3/envs/BOS/lib/python3.8/concurrent/futures/thread.py", line 57, in run
    result = self.fn(*self.args, **self.kwargs)
  File "/home/bookofscotland/miniconda3/envs/BOS/lib/python3.8/site-packages/asgiref/sync.py", line 538, in thread_handler
    return func(*args, **kwargs)
  File "/var/www/bookscot/public_site/views.py", line 70, in directory_main_view
    directory = get_object_or_404(Directory, id=directory_id)
  File "/home/bookofscotland/miniconda3/envs/BOS/lib/python3.8/site-packages/django/shortcuts.py", line 85, in get_object_or_404
    return queryset.get(*args, **kwargs)
  File "/home/bookofscotland/miniconda3/envs/BOS/lib/python3.8/site-packages/django/db/models/query.py", line 646, in get
    num = len(clone)
  File "/home/bookofscotland/miniconda3/envs/BOS/lib/python3.8/site-packages/django/db/models/query.py", line 376, in __len__
    self._fetch_all()
  File "/home/bookofscotland/miniconda3/envs/BOS/lib/python3.8/site-packages/django/db/models/query.py", line 1866, in _fetch_all
    self._result_cache = list(self._iterable_class(self))
  File "/home/bookofscotland/miniconda3/envs/BOS/lib/python3.8/site-packages/django/db/models/query.py", line 87, in __iter__
    results = compiler.execute_sql(
  File "/home/bookofscotland/miniconda3/envs/BOS/lib/python3.8/site-packages/django/db/models/sql/compiler.py", line 1395, in execute_sql
    cursor.execute(sql, params)
  File "/home/bookofscotland/miniconda3/envs/BOS/lib/python3.8/site-packages/django/db/backends/utils.py", line 67, in execute
    return self._execute_with_wrappers(
  File "/home/bookofscotland/miniconda3/envs/BOS/lib/python3.8/site-packages/django/db/backends/utils.py", line 80, in _execute_with_wrappers
    return executor(sql, params, many, context)
  File "/home/bookofscotland/miniconda3/envs/BOS/lib/python3.8/site-packages/django/db/backends/utils.py", line 89, in _execute
    return self.cursor.execute(sql, params)
  File "/home/bookofscotland/miniconda3/envs/BOS/lib/python3.8/site-packages/django/db/utils.py", line 91, in __exit__
    raise dj_exc_value.with_traceback(traceback) from exc_value
  File "/home/bookofscotland/miniconda3/envs/BOS/lib/python3.8/site-packages/django/db/backends/utils.py", line 89, in _execute
    return self.cursor.execute(sql, params)
  File "/home/bookofscotland/miniconda3/envs/BOS/lib/python3.8/site-packages/django/db/backends/mysql/base.py", line 75, in execute
    return self.cursor.execute(query, args)
  File "/home/bookofscotland/miniconda3/envs/BOS/lib/python3.8/site-packages/MySQLdb/cursors.py", line 179, in execute
    res = self._query(mogrified_query)
  File "/home/bookofscotland/miniconda3/envs/BOS/lib/python3.8/site-packages/MySQLdb/cursors.py", line 330, in _query
    db.query(q)
  File "/home/bookofscotland/miniconda3/envs/BOS/lib/python3.8/site-packages/MySQLdb/connections.py", line 261, in query
    _mysql.connection.query(self, query)
django.db.utils.ProgrammingError: (1146, "Table 'aibos_django.bookscot_site_directory' doesn't exist")
Internal Server Error: /directory/9/
Traceback (most recent call last):
  File "/home/bookofscotland/miniconda3/envs/BOS/lib/python3.8/site-packages/django/db/backends/utils.py", line 89, in _execute
    return self.cursor.execute(sql, params)
  File "/home/bookofscotland/miniconda3/envs/BOS/lib/python3.8/site-packages/django/db/backends/mysql/base.py", line 75, in execute
    return self.cursor.execute(query, args)
  File "/home/bookofscotland/miniconda3/envs/BOS/lib/python3.8/site-packages/MySQLdb/cursors.py", line 179, in execute
    res = self._query(mogrified_query)
  File "/home/bookofscotland/miniconda3/envs/BOS/lib/python3.8/site-packages/MySQLdb/cursors.py", line 330, in _query
    db.query(q)
  File "/home/bookofscotland/miniconda3/envs/BOS/lib/python3.8/site-packages/MySQLdb/connections.py", line 261, in query
    _mysql.connection.query(self, query)
MySQLdb.ProgrammingError: (1146, "Table 'aibos_django.bookscot_site_directory' doesn't exist")

The above exception was the direct cause of the following exception:

Traceback (most recent call last):
  File "/home/bookofscotland/miniconda3/envs/BOS/lib/python3.8/site-packages/asgiref/sync.py", line 534, in thread_handler
    raise exc_info[1]
  File "/home/bookofscotland/miniconda3/envs/BOS/lib/python3.8/site-packages/django/core/handlers/exception.py", line 42, in inner
    response = await get_response(request)
  File "/home/bookofscotland/miniconda3/envs/BOS/lib/python3.8/site-packages/django/core/handlers/base.py", line 253, in _get_response_async
    response = await wrapped_callback(
  File "/home/bookofscotland/miniconda3/envs/BOS/lib/python3.8/site-packages/asgiref/sync.py", line 479, in __call__
    ret: _R = await loop.run_in_executor(
  File "/home/bookofscotland/miniconda3/envs/BOS/lib/python3.8/concurrent/futures/thread.py", line 57, in run
    result = self.fn(*self.args, **self.kwargs)
  File "/home/bookofscotland/miniconda3/envs/BOS/lib/python3.8/site-packages/asgiref/sync.py", line 538, in thread_handler
    return func(*args, **kwargs)
  File "/var/www/bookscot/public_site/views.py", line 70, in directory_main_view
    directory = get_object_or_404(Directory, id=directory_id)
  File "/home/bookofscotland/miniconda3/envs/BOS/lib/python3.8/site-packages/django/shortcuts.py", line 85, in get_object_or_404
    return queryset.get(*args, **kwargs)
  File "/home/bookofscotland/miniconda3/envs/BOS/lib/python3.8/site-packages/django/db/models/query.py", line 646, in get
    num = len(clone)
  File "/home/bookofscotland/miniconda3/envs/BOS/lib/python3.8/site-packages/django/db/models/query.py", line 376, in __len__
    self._fetch_all()
  File "/home/bookofscotland/miniconda3/envs/BOS/lib/python3.8/site-packages/django/db/models/query.py", line 1866, in _fetch_all
    self._result_cache = list(self._iterable_class(self))
  File "/home/bookofscotland/miniconda3/envs/BOS/lib/python3.8/site-packages/django/db/models/query.py", line 87, in __iter__
    results = compiler.execute_sql(
  File "/home/bookofscotland/miniconda3/envs/BOS/lib/python3.8/site-packages/django/db/models/sql/compiler.py", line 1395, in execute_sql
    cursor.execute(sql, params)
  File "/home/bookofscotland/miniconda3/envs/BOS/lib/python3.8/site-packages/django/db/backends/utils.py", line 67, in execute
    return self._execute_with_wrappers(
  File "/home/bookofscotland/miniconda3/envs/BOS/lib/python3.8/site-packages/django/db/backends/utils.py", line 80, in _execute_with_wrappers
    return executor(sql, params, many, context)
  File "/home/bookofscotland/miniconda3/envs/BOS/lib/python3.8/site-packages/django/db/backends/utils.py", line 89, in _execute
    return self.cursor.execute(sql, params)
  File "/home/bookofscotland/miniconda3/envs/BOS/lib/python3.8/site-packages/django/db/utils.py", line 91, in __exit__
    raise dj_exc_value.with_traceback(traceback) from exc_value
  File "/home/bookofscotland/miniconda3/envs/BOS/lib/python3.8/site-packages/django/db/backends/utils.py", line 89, in _execute
    return self.cursor.execute(sql, params)
  File "/home/bookofscotland/miniconda3/envs/BOS/lib/python3.8/site-packages/django/db/backends/mysql/base.py", line 75, in execute
    return self.cursor.execute(query, args)
  File "/home/bookofscotland/miniconda3/envs/BOS/lib/python3.8/site-packages/MySQLdb/cursors.py", line 179, in execute
    res = self._query(mogrified_query)
  File "/home/bookofscotland/miniconda3/envs/BOS/lib/python3.8/site-packages/MySQLdb/cursors.py", line 330, in _query
    db.query(q)
  File "/home/bookofscotland/miniconda3/envs/BOS/lib/python3.8/site-packages/MySQLdb/connections.py", line 261, in query
    _mysql.connection.query(self, query)
django.db.utils.ProgrammingError: (1146, "Table 'aibos_django.bookscot_site_directory' doesn't exist")
Internal Server Error: /directory/10/
Traceback (most recent call last):
  File "/home/bookofscotland/miniconda3/envs/BOS/lib/python3.8/site-packages/django/db/backends/utils.py", line 89, in _execute
    return self.cursor.execute(sql, params)
  File "/home/bookofscotland/miniconda3/envs/BOS/lib/python3.8/site-packages/django/db/backends/mysql/base.py", line 75, in execute
    return self.cursor.execute(query, args)
  File "/home/bookofscotland/miniconda3/envs/BOS/lib/python3.8/site-packages/MySQLdb/cursors.py", line 179, in execute
    res = self._query(mogrified_query)
  File "/home/bookofscotland/miniconda3/envs/BOS/lib/python3.8/site-packages/MySQLdb/cursors.py", line 330, in _query
    db.query(q)
  File "/home/bookofscotland/miniconda3/envs/BOS/lib/python3.8/site-packages/MySQLdb/connections.py", line 261, in query
    _mysql.connection.query(self, query)
MySQLdb.ProgrammingError: (1146, "Table 'aibos_django.bookscot_site_directory' doesn't exist")

The above exception was the direct cause of the following exception:

Traceback (most recent call last):
  File "/home/bookofscotland/miniconda3/envs/BOS/lib/python3.8/site-packages/asgiref/sync.py", line 534, in thread_handler
    raise exc_info[1]
  File "/home/bookofscotland/miniconda3/envs/BOS/lib/python3.8/site-packages/django/core/handlers/exception.py", line 42, in inner
    response = await get_response(request)
  File "/home/bookofscotland/miniconda3/envs/BOS/lib/python3.8/site-packages/django/core/handlers/base.py", line 253, in _get_response_async
    response = await wrapped_callback(
  File "/home/bookofscotland/miniconda3/envs/BOS/lib/python3.8/site-packages/asgiref/sync.py", line 479, in __call__
    ret: _R = await loop.run_in_executor(
  File "/home/bookofscotland/miniconda3/envs/BOS/lib/python3.8/concurrent/futures/thread.py", line 57, in run
    result = self.fn(*self.args, **self.kwargs)
  File "/home/bookofscotland/miniconda3/envs/BOS/lib/python3.8/site-packages/asgiref/sync.py", line 538, in thread_handler
    return func(*args, **kwargs)
  File "/var/www/bookscot/public_site/views.py", line 70, in directory_main_view
    directory = get_object_or_404(Directory, id=directory_id)
  File "/home/bookofscotland/miniconda3/envs/BOS/lib/python3.8/site-packages/django/shortcuts.py", line 85, in get_object_or_404
    return queryset.get(*args, **kwargs)
  File "/home/bookofscotland/miniconda3/envs/BOS/lib/python3.8/site-packages/django/db/models/query.py", line 646, in get
    num = len(clone)
  File "/home/bookofscotland/miniconda3/envs/BOS/lib/python3.8/site-packages/django/db/models/query.py", line 376, in __len__
    self._fetch_all()
  File "/home/bookofscotland/miniconda3/envs/BOS/lib/python3.8/site-packages/django/db/models/query.py", line 1866, in _fetch_all
    self._result_cache = list(self._iterable_class(self))
  File "/home/bookofscotland/miniconda3/envs/BOS/lib/python3.8/site-packages/django/db/models/query.py", line 87, in __iter__
    results = compiler.execute_sql(
  File "/home/bookofscotland/miniconda3/envs/BOS/lib/python3.8/site-packages/django/db/models/sql/compiler.py", line 1395, in execute_sql
    cursor.execute(sql, params)
  File "/home/bookofscotland/miniconda3/envs/BOS/lib/python3.8/site-packages/django/db/backends/utils.py", line 67, in execute
    return self._execute_with_wrappers(
  File "/home/bookofscotland/miniconda3/envs/BOS/lib/python3.8/site-packages/django/db/backends/utils.py", line 80, in _execute_with_wrappers
    return executor(sql, params, many, context)
  File "/home/bookofscotland/miniconda3/envs/BOS/lib/python3.8/site-packages/django/db/backends/utils.py", line 89, in _execute
    return self.cursor.execute(sql, params)
  File "/home/bookofscotland/miniconda3/envs/BOS/lib/python3.8/site-packages/django/db/utils.py", line 91, in __exit__
    raise dj_exc_value.with_traceback(traceback) from exc_value
  File "/home/bookofscotland/miniconda3/envs/BOS/lib/python3.8/site-packages/django/db/backends/utils.py", line 89, in _execute
    return self.cursor.execute(sql, params)
  File "/home/bookofscotland/miniconda3/envs/BOS/lib/python3.8/site-packages/django/db/backends/mysql/base.py", line 75, in execute
    return self.cursor.execute(query, args)
  File "/home/bookofscotland/miniconda3/envs/BOS/lib/python3.8/site-packages/MySQLdb/cursors.py", line 179, in execute
    res = self._query(mogrified_query)
  File "/home/bookofscotland/miniconda3/envs/BOS/lib/python3.8/site-packages/MySQLdb/cursors.py", line 330, in _query
    db.query(q)
  File "/home/bookofscotland/miniconda3/envs/BOS/lib/python3.8/site-packages/MySQLdb/connections.py", line 261, in query
    _mysql.connection.query(self, query)
django.db.utils.ProgrammingError: (1146, "Table 'aibos_django.bookscot_site_directory' doesn't exist")
Internal Server Error: /directory/25/
Traceback (most recent call last):
  File "/home/bookofscotland/miniconda3/envs/BOS/lib/python3.8/site-packages/django/db/backends/utils.py", line 89, in _execute
    return self.cursor.execute(sql, params)
  File "/home/bookofscotland/miniconda3/envs/BOS/lib/python3.8/site-packages/django/db/backends/mysql/base.py", line 75, in execute
    return self.cursor.execute(query, args)
  File "/home/bookofscotland/miniconda3/envs/BOS/lib/python3.8/site-packages/MySQLdb/cursors.py", line 179, in execute
    res = self._query(mogrified_query)
  File "/home/bookofscotland/miniconda3/envs/BOS/lib/python3.8/site-packages/MySQLdb/cursors.py", line 330, in _query
    db.query(q)
  File "/home/bookofscotland/miniconda3/envs/BOS/lib/python3.8/site-packages/MySQLdb/connections.py", line 261, in query
    _mysql.connection.query(self, query)
MySQLdb.ProgrammingError: (1146, "Table 'aibos_django.bookscot_site_directory' doesn't exist")

The above exception was the direct cause of the following exception:

Traceback (most recent call last):
  File "/home/bookofscotland/miniconda3/envs/BOS/lib/python3.8/site-packages/asgiref/sync.py", line 534, in thread_handler
    raise exc_info[1]
  File "/home/bookofscotland/miniconda3/envs/BOS/lib/python3.8/site-packages/django/core/handlers/exception.py", line 42, in inner
    response = await get_response(request)
  File "/home/bookofscotland/miniconda3/envs/BOS/lib/python3.8/site-packages/django/core/handlers/base.py", line 253, in _get_response_async
    response = await wrapped_callback(
  File "/home/bookofscotland/miniconda3/envs/BOS/lib/python3.8/site-packages/asgiref/sync.py", line 479, in __call__
    ret: _R = await loop.run_in_executor(
  File "/home/bookofscotland/miniconda3/envs/BOS/lib/python3.8/concurrent/futures/thread.py", line 57, in run
    result = self.fn(*self.args, **self.kwargs)
  File "/home/bookofscotland/miniconda3/envs/BOS/lib/python3.8/site-packages/asgiref/sync.py", line 538, in thread_handler
    return func(*args, **kwargs)
  File "/var/www/bookscot/public_site/views.py", line 70, in directory_main_view
    directory = get_object_or_404(Directory, id=directory_id)
  File "/home/bookofscotland/miniconda3/envs/BOS/lib/python3.8/site-packages/django/shortcuts.py", line 85, in get_object_or_404
    return queryset.get(*args, **kwargs)
  File "/home/bookofscotland/miniconda3/envs/BOS/lib/python3.8/site-packages/django/db/models/query.py", line 646, in get
    num = len(clone)
  File "/home/bookofscotland/miniconda3/envs/BOS/lib/python3.8/site-packages/django/db/models/query.py", line 376, in __len__
    self._fetch_all()
  File "/home/bookofscotland/miniconda3/envs/BOS/lib/python3.8/site-packages/django/db/models/query.py", line 1866, in _fetch_all
    self._result_cache = list(self._iterable_class(self))
  File "/home/bookofscotland/miniconda3/envs/BOS/lib/python3.8/site-packages/django/db/models/query.py", line 87, in __iter__
    results = compiler.execute_sql(
  File "/home/bookofscotland/miniconda3/envs/BOS/lib/python3.8/site-packages/django/db/models/sql/compiler.py", line 1395, in execute_sql
    cursor.execute(sql, params)
  File "/home/bookofscotland/miniconda3/envs/BOS/lib/python3.8/site-packages/django/db/backends/utils.py", line 67, in execute
    return self._execute_with_wrappers(
  File "/home/bookofscotland/miniconda3/envs/BOS/lib/python3.8/site-packages/django/db/backends/utils.py", line 80, in _execute_with_wrappers
    return executor(sql, params, many, context)
  File "/home/bookofscotland/miniconda3/envs/BOS/lib/python3.8/site-packages/django/db/backends/utils.py", line 89, in _execute
    return self.cursor.execute(sql, params)
  File "/home/bookofscotland/miniconda3/envs/BOS/lib/python3.8/site-packages/django/db/utils.py", line 91, in __exit__
    raise dj_exc_value.with_traceback(traceback) from exc_value
  File "/home/bookofscotland/miniconda3/envs/BOS/lib/python3.8/site-packages/django/db/backends/utils.py", line 89, in _execute
    return self.cursor.execute(sql, params)
  File "/home/bookofscotland/miniconda3/envs/BOS/lib/python3.8/site-packages/django/db/backends/mysql/base.py", line 75, in execute
    return self.cursor.execute(query, args)
  File "/home/bookofscotland/miniconda3/envs/BOS/lib/python3.8/site-packages/MySQLdb/cursors.py", line 179, in execute
    res = self._query(mogrified_query)
  File "/home/bookofscotland/miniconda3/envs/BOS/lib/python3.8/site-packages/MySQLdb/cursors.py", line 330, in _query
    db.query(q)
  File "/home/bookofscotland/miniconda3/envs/BOS/lib/python3.8/site-packages/MySQLdb/connections.py", line 261, in query
    _mysql.connection.query(self, query)
django.db.utils.ProgrammingError: (1146, "Table 'aibos_django.bookscot_site_directory' doesn't exist")
Internal Server Error: /directory/30/
Traceback (most recent call last):
  File "/home/bookofscotland/miniconda3/envs/BOS/lib/python3.8/site-packages/django/db/backends/utils.py", line 89, in _execute
    return self.cursor.execute(sql, params)
  File "/home/bookofscotland/miniconda3/envs/BOS/lib/python3.8/site-packages/django/db/backends/mysql/base.py", line 75, in execute
    return self.cursor.execute(query, args)
  File "/home/bookofscotland/miniconda3/envs/BOS/lib/python3.8/site-packages/MySQLdb/cursors.py", line 179, in execute
    res = self._query(mogrified_query)
  File "/home/bookofscotland/miniconda3/envs/BOS/lib/python3.8/site-packages/MySQLdb/cursors.py", line 330, in _query
    db.query(q)
  File "/home/bookofscotland/miniconda3/envs/BOS/lib/python3.8/site-packages/MySQLdb/connections.py", line 261, in query
    _mysql.connection.query(self, query)
MySQLdb.ProgrammingError: (1146, "Table 'aibos_django.bookscot_site_directory' doesn't exist")

The above exception was the direct cause of the following exception:

Traceback (most recent call last):
  File "/home/bookofscotland/miniconda3/envs/BOS/lib/python3.8/site-packages/asgiref/sync.py", line 534, in thread_handler
    raise exc_info[1]
  File "/home/bookofscotland/miniconda3/envs/BOS/lib/python3.8/site-packages/django/core/handlers/exception.py", line 42, in inner
    response = await get_response(request)
  File "/home/bookofscotland/miniconda3/envs/BOS/lib/python3.8/site-packages/django/core/handlers/base.py", line 253, in _get_response_async
    response = await wrapped_callback(
  File "/home/bookofscotland/miniconda3/envs/BOS/lib/python3.8/site-packages/asgiref/sync.py", line 479, in __call__
    ret: _R = await loop.run_in_executor(
  File "/home/bookofscotland/miniconda3/envs/BOS/lib/python3.8/concurrent/futures/thread.py", line 57, in run
    result = self.fn(*self.args, **self.kwargs)
  File "/home/bookofscotland/miniconda3/envs/BOS/lib/python3.8/site-packages/asgiref/sync.py", line 538, in thread_handler
    return func(*args, **kwargs)
  File "/var/www/bookscot/public_site/views.py", line 70, in directory_main_view
    directory = get_object_or_404(Directory, id=directory_id)
  File "/home/bookofscotland/miniconda3/envs/BOS/lib/python3.8/site-packages/django/shortcuts.py", line 85, in get_object_or_404
    return queryset.get(*args, **kwargs)
  File "/home/bookofscotland/miniconda3/envs/BOS/lib/python3.8/site-packages/django/db/models/query.py", line 646, in get
    num = len(clone)
  File "/home/bookofscotland/miniconda3/envs/BOS/lib/python3.8/site-packages/django/db/models/query.py", line 376, in __len__
    self._fetch_all()
  File "/home/bookofscotland/miniconda3/envs/BOS/lib/python3.8/site-packages/django/db/models/query.py", line 1866, in _fetch_all
    self._result_cache = list(self._iterable_class(self))
  File "/home/bookofscotland/miniconda3/envs/BOS/lib/python3.8/site-packages/django/db/models/query.py", line 87, in __iter__
    results = compiler.execute_sql(
  File "/home/bookofscotland/miniconda3/envs/BOS/lib/python3.8/site-packages/django/db/models/sql/compiler.py", line 1395, in execute_sql
    cursor.execute(sql, params)
  File "/home/bookofscotland/miniconda3/envs/BOS/lib/python3.8/site-packages/django/db/backends/utils.py", line 67, in execute
    return self._execute_with_wrappers(
  File "/home/bookofscotland/miniconda3/envs/BOS/lib/python3.8/site-packages/django/db/backends/utils.py", line 80, in _execute_with_wrappers
    return executor(sql, params, many, context)
  File "/home/bookofscotland/miniconda3/envs/BOS/lib/python3.8/site-packages/django/db/backends/utils.py", line 89, in _execute
    return self.cursor.execute(sql, params)
  File "/home/bookofscotland/miniconda3/envs/BOS/lib/python3.8/site-packages/django/db/utils.py", line 91, in __exit__
    raise dj_exc_value.with_traceback(traceback) from exc_value
  File "/home/bookofscotland/miniconda3/envs/BOS/lib/python3.8/site-packages/django/db/backends/utils.py", line 89, in _execute
    return self.cursor.execute(sql, params)
  File "/home/bookofscotland/miniconda3/envs/BOS/lib/python3.8/site-packages/django/db/backends/mysql/base.py", line 75, in execute
    return self.cursor.execute(query, args)
  File "/home/bookofscotland/miniconda3/envs/BOS/lib/python3.8/site-packages/MySQLdb/cursors.py", line 179, in execute
    res = self._query(mogrified_query)
  File "/home/bookofscotland/miniconda3/envs/BOS/lib/python3.8/site-packages/MySQLdb/cursors.py", line 330, in _query
    db.query(q)
  File "/home/bookofscotland/miniconda3/envs/BOS/lib/python3.8/site-packages/MySQLdb/connections.py", line 261, in query
    _mysql.connection.query(self, query)
django.db.utils.ProgrammingError: (1146, "Table 'aibos_django.bookscot_site_directory' doesn't exist")
Internal Server Error: /directory/31/
Traceback (most recent call last):
  File "/home/bookofscotland/miniconda3/envs/BOS/lib/python3.8/site-packages/django/db/backends/utils.py", line 89, in _execute
    return self.cursor.execute(sql, params)
  File "/home/bookofscotland/miniconda3/envs/BOS/lib/python3.8/site-packages/django/db/backends/mysql/base.py", line 75, in execute
    return self.cursor.execute(query, args)
  File "/home/bookofscotland/miniconda3/envs/BOS/lib/python3.8/site-packages/MySQLdb/cursors.py", line 179, in execute
    res = self._query(mogrified_query)
  File "/home/bookofscotland/miniconda3/envs/BOS/lib/python3.8/site-packages/MySQLdb/cursors.py", line 330, in _query
    db.query(q)
  File "/home/bookofscotland/miniconda3/envs/BOS/lib/python3.8/site-packages/MySQLdb/connections.py", line 261, in query
    _mysql.connection.query(self, query)
MySQLdb.ProgrammingError: (1146, "Table 'aibos_django.bookscot_site_directory' doesn't exist")

The above exception was the direct cause of the following exception:

Traceback (most recent call last):
  File "/home/bookofscotland/miniconda3/envs/BOS/lib/python3.8/site-packages/asgiref/sync.py", line 534, in thread_handler
    raise exc_info[1]
  File "/home/bookofscotland/miniconda3/envs/BOS/lib/python3.8/site-packages/django/core/handlers/exception.py", line 42, in inner
    response = await get_response(request)
  File "/home/bookofscotland/miniconda3/envs/BOS/lib/python3.8/site-packages/django/core/handlers/base.py", line 253, in _get_response_async
    response = await wrapped_callback(
  File "/home/bookofscotland/miniconda3/envs/BOS/lib/python3.8/site-packages/asgiref/sync.py", line 479, in __call__
    ret: _R = await loop.run_in_executor(
  File "/home/bookofscotland/miniconda3/envs/BOS/lib/python3.8/concurrent/futures/thread.py", line 57, in run
    result = self.fn(*self.args, **self.kwargs)
  File "/home/bookofscotland/miniconda3/envs/BOS/lib/python3.8/site-packages/asgiref/sync.py", line 538, in thread_handler
    return func(*args, **kwargs)
  File "/var/www/bookscot/public_site/views.py", line 70, in directory_main_view
    directory = get_object_or_404(Directory, id=directory_id)
  File "/home/bookofscotland/miniconda3/envs/BOS/lib/python3.8/site-packages/django/shortcuts.py", line 85, in get_object_or_404
    return queryset.get(*args, **kwargs)
  File "/home/bookofscotland/miniconda3/envs/BOS/lib/python3.8/site-packages/django/db/models/query.py", line 646, in get
    num = len(clone)
  File "/home/bookofscotland/miniconda3/envs/BOS/lib/python3.8/site-packages/django/db/models/query.py", line 376, in __len__
    self._fetch_all()
  File "/home/bookofscotland/miniconda3/envs/BOS/lib/python3.8/site-packages/django/db/models/query.py", line 1866, in _fetch_all
    self._result_cache = list(self._iterable_class(self))
  File "/home/bookofscotland/miniconda3/envs/BOS/lib/python3.8/site-packages/django/db/models/query.py", line 87, in __iter__
    results = compiler.execute_sql(
  File "/home/bookofscotland/miniconda3/envs/BOS/lib/python3.8/site-packages/django/db/models/sql/compiler.py", line 1395, in execute_sql
    cursor.execute(sql, params)
  File "/home/bookofscotland/miniconda3/envs/BOS/lib/python3.8/site-packages/django/db/backends/utils.py", line 67, in execute
    return self._execute_with_wrappers(
  File "/home/bookofscotland/miniconda3/envs/BOS/lib/python3.8/site-packages/django/db/backends/utils.py", line 80, in _execute_with_wrappers
    return executor(sql, params, many, context)
  File "/home/bookofscotland/miniconda3/envs/BOS/lib/python3.8/site-packages/django/db/backends/utils.py", line 89, in _execute
    return self.cursor.execute(sql, params)
  File "/home/bookofscotland/miniconda3/envs/BOS/lib/python3.8/site-packages/django/db/utils.py", line 91, in __exit__
    raise dj_exc_value.with_traceback(traceback) from exc_value
  File "/home/bookofscotland/miniconda3/envs/BOS/lib/python3.8/site-packages/django/db/backends/utils.py", line 89, in _execute
    return self.cursor.execute(sql, params)
  File "/home/bookofscotland/miniconda3/envs/BOS/lib/python3.8/site-packages/django/db/backends/mysql/base.py", line 75, in execute
    return self.cursor.execute(query, args)
  File "/home/bookofscotland/miniconda3/envs/BOS/lib/python3.8/site-packages/MySQLdb/cursors.py", line 179, in execute
    res = self._query(mogrified_query)
  File "/home/bookofscotland/miniconda3/envs/BOS/lib/python3.8/site-packages/MySQLdb/cursors.py", line 330, in _query
    db.query(q)
  File "/home/bookofscotland/miniconda3/envs/BOS/lib/python3.8/site-packages/MySQLdb/connections.py", line 261, in query
    _mysql.connection.query(self, query)
django.db.utils.ProgrammingError: (1146, "Table 'aibos_django.bookscot_site_directory' doesn't exist")
Internal Server Error: /directory/32/
Traceback (most recent call last):
  File "/home/bookofscotland/miniconda3/envs/BOS/lib/python3.8/site-packages/django/db/backends/utils.py", line 89, in _execute
    return self.cursor.execute(sql, params)
  File "/home/bookofscotland/miniconda3/envs/BOS/lib/python3.8/site-packages/django/db/backends/mysql/base.py", line 75, in execute
    return self.cursor.execute(query, args)
  File "/home/bookofscotland/miniconda3/envs/BOS/lib/python3.8/site-packages/MySQLdb/cursors.py", line 179, in execute
    res = self._query(mogrified_query)
  File "/home/bookofscotland/miniconda3/envs/BOS/lib/python3.8/site-packages/MySQLdb/cursors.py", line 330, in _query
    db.query(q)
  File "/home/bookofscotland/miniconda3/envs/BOS/lib/python3.8/site-packages/MySQLdb/connections.py", line 261, in query
    _mysql.connection.query(self, query)
MySQLdb.ProgrammingError: (1146, "Table 'aibos_django.bookscot_site_directory' doesn't exist")

The above exception was the direct cause of the following exception:

Traceback (most recent call last):
  File "/home/bookofscotland/miniconda3/envs/BOS/lib/python3.8/site-packages/asgiref/sync.py", line 534, in thread_handler
    raise exc_info[1]
  File "/home/bookofscotland/miniconda3/envs/BOS/lib/python3.8/site-packages/django/core/handlers/exception.py", line 42, in inner
    response = await get_response(request)
  File "/home/bookofscotland/miniconda3/envs/BOS/lib/python3.8/site-packages/django/core/handlers/base.py", line 253, in _get_response_async
    response = await wrapped_callback(
  File "/home/bookofscotland/miniconda3/envs/BOS/lib/python3.8/site-packages/asgiref/sync.py", line 479, in __call__
    ret: _R = await loop.run_in_executor(
  File "/home/bookofscotland/miniconda3/envs/BOS/lib/python3.8/concurrent/futures/thread.py", line 57, in run
    result = self.fn(*self.args, **self.kwargs)
  File "/home/bookofscotland/miniconda3/envs/BOS/lib/python3.8/site-packages/asgiref/sync.py", line 538, in thread_handler
    return func(*args, **kwargs)
  File "/var/www/bookscot/public_site/views.py", line 70, in directory_main_view
    directory = get_object_or_404(Directory, id=directory_id)
  File "/home/bookofscotland/miniconda3/envs/BOS/lib/python3.8/site-packages/django/shortcuts.py", line 85, in get_object_or_404
    return queryset.get(*args, **kwargs)
  File "/home/bookofscotland/miniconda3/envs/BOS/lib/python3.8/site-packages/django/db/models/query.py", line 646, in get
    num = len(clone)
  File "/home/bookofscotland/miniconda3/envs/BOS/lib/python3.8/site-packages/django/db/models/query.py", line 376, in __len__
    self._fetch_all()
  File "/home/bookofscotland/miniconda3/envs/BOS/lib/python3.8/site-packages/django/db/models/query.py", line 1866, in _fetch_all
    self._result_cache = list(self._iterable_class(self))
  File "/home/bookofscotland/miniconda3/envs/BOS/lib/python3.8/site-packages/django/db/models/query.py", line 87, in __iter__
    results = compiler.execute_sql(
  File "/home/bookofscotland/miniconda3/envs/BOS/lib/python3.8/site-packages/django/db/models/sql/compiler.py", line 1395, in execute_sql
    cursor.execute(sql, params)
  File "/home/bookofscotland/miniconda3/envs/BOS/lib/python3.8/site-packages/django/db/backends/utils.py", line 67, in execute
    return self._execute_with_wrappers(
  File "/home/bookofscotland/miniconda3/envs/BOS/lib/python3.8/site-packages/django/db/backends/utils.py", line 80, in _execute_with_wrappers
    return executor(sql, params, many, context)
  File "/home/bookofscotland/miniconda3/envs/BOS/lib/python3.8/site-packages/django/db/backends/utils.py", line 89, in _execute
    return self.cursor.execute(sql, params)
  File "/home/bookofscotland/miniconda3/envs/BOS/lib/python3.8/site-packages/django/db/utils.py", line 91, in __exit__
    raise dj_exc_value.with_traceback(traceback) from exc_value
  File "/home/bookofscotland/miniconda3/envs/BOS/lib/python3.8/site-packages/django/db/backends/utils.py", line 89, in _execute
    return self.cursor.execute(sql, params)
  File "/home/bookofscotland/miniconda3/envs/BOS/lib/python3.8/site-packages/django/db/backends/mysql/base.py", line 75, in execute
    return self.cursor.execute(query, args)
  File "/home/bookofscotland/miniconda3/envs/BOS/lib/python3.8/site-packages/MySQLdb/cursors.py", line 179, in execute
    res = self._query(mogrified_query)
  File "/home/bookofscotland/miniconda3/envs/BOS/lib/python3.8/site-packages/MySQLdb/cursors.py", line 330, in _query
    db.query(q)
  File "/home/bookofscotland/miniconda3/envs/BOS/lib/python3.8/site-packages/MySQLdb/connections.py", line 261, in query
    _mysql.connection.query(self, query)
django.db.utils.ProgrammingError: (1146, "Table 'aibos_django.bookscot_site_directory' doesn't exist")
Internal Server Error: /directory/23/
Traceback (most recent call last):
  File "/home/bookofscotland/miniconda3/envs/BOS/lib/python3.8/site-packages/django/db/backends/utils.py", line 89, in _execute
    return self.cursor.execute(sql, params)
  File "/home/bookofscotland/miniconda3/envs/BOS/lib/python3.8/site-packages/django/db/backends/mysql/base.py", line 75, in execute
    return self.cursor.execute(query, args)
  File "/home/bookofscotland/miniconda3/envs/BOS/lib/python3.8/site-packages/MySQLdb/cursors.py", line 179, in execute
    res = self._query(mogrified_query)
  File "/home/bookofscotland/miniconda3/envs/BOS/lib/python3.8/site-packages/MySQLdb/cursors.py", line 330, in _query
    db.query(q)
  File "/home/bookofscotland/miniconda3/envs/BOS/lib/python3.8/site-packages/MySQLdb/connections.py", line 261, in query
    _mysql.connection.query(self, query)
MySQLdb.ProgrammingError: (1146, "Table 'aibos_django.bookscot_site_directory' doesn't exist")

The above exception was the direct cause of the following exception:

Traceback (most recent call last):
  File "/home/bookofscotland/miniconda3/envs/BOS/lib/python3.8/site-packages/asgiref/sync.py", line 534, in thread_handler
    raise exc_info[1]
  File "/home/bookofscotland/miniconda3/envs/BOS/lib/python3.8/site-packages/django/core/handlers/exception.py", line 42, in inner
    response = await get_response(request)
  File "/home/bookofscotland/miniconda3/envs/BOS/lib/python3.8/site-packages/django/core/handlers/base.py", line 253, in _get_response_async
    response = await wrapped_callback(
  File "/home/bookofscotland/miniconda3/envs/BOS/lib/python3.8/site-packages/asgiref/sync.py", line 479, in __call__
    ret: _R = await loop.run_in_executor(
  File "/home/bookofscotland/miniconda3/envs/BOS/lib/python3.8/concurrent/futures/thread.py", line 57, in run
    result = self.fn(*self.args, **self.kwargs)
  File "/home/bookofscotland/miniconda3/envs/BOS/lib/python3.8/site-packages/asgiref/sync.py", line 538, in thread_handler
    return func(*args, **kwargs)
  File "/var/www/bookscot/public_site/views.py", line 70, in directory_main_view
    directory = get_object_or_404(Directory, id=directory_id)
  File "/home/bookofscotland/miniconda3/envs/BOS/lib/python3.8/site-packages/django/shortcuts.py", line 85, in get_object_or_404
    return queryset.get(*args, **kwargs)
  File "/home/bookofscotland/miniconda3/envs/BOS/lib/python3.8/site-packages/django/db/models/query.py", line 646, in get
    num = len(clone)
  File "/home/bookofscotland/miniconda3/envs/BOS/lib/python3.8/site-packages/django/db/models/query.py", line 376, in __len__
    self._fetch_all()
  File "/home/bookofscotland/miniconda3/envs/BOS/lib/python3.8/site-packages/django/db/models/query.py", line 1866, in _fetch_all
    self._result_cache = list(self._iterable_class(self))
  File "/home/bookofscotland/miniconda3/envs/BOS/lib/python3.8/site-packages/django/db/models/query.py", line 87, in __iter__
    results = compiler.execute_sql(
  File "/home/bookofscotland/miniconda3/envs/BOS/lib/python3.8/site-packages/django/db/models/sql/compiler.py", line 1395, in execute_sql
    cursor.execute(sql, params)
  File "/home/bookofscotland/miniconda3/envs/BOS/lib/python3.8/site-packages/django/db/backends/utils.py", line 67, in execute
    return self._execute_with_wrappers(
  File "/home/bookofscotland/miniconda3/envs/BOS/lib/python3.8/site-packages/django/db/backends/utils.py", line 80, in _execute_with_wrappers
    return executor(sql, params, many, context)
  File "/home/bookofscotland/miniconda3/envs/BOS/lib/python3.8/site-packages/django/db/backends/utils.py", line 89, in _execute
    return self.cursor.execute(sql, params)
  File "/home/bookofscotland/miniconda3/envs/BOS/lib/python3.8/site-packages/django/db/utils.py", line 91, in __exit__
    raise dj_exc_value.with_traceback(traceback) from exc_value
  File "/home/bookofscotland/miniconda3/envs/BOS/lib/python3.8/site-packages/django/db/backends/utils.py", line 89, in _execute
    return self.cursor.execute(sql, params)
  File "/home/bookofscotland/miniconda3/envs/BOS/lib/python3.8/site-packages/django/db/backends/mysql/base.py", line 75, in execute
    return self.cursor.execute(query, args)
  File "/home/bookofscotland/miniconda3/envs/BOS/lib/python3.8/site-packages/MySQLdb/cursors.py", line 179, in execute
    res = self._query(mogrified_query)
  File "/home/bookofscotland/miniconda3/envs/BOS/lib/python3.8/site-packages/MySQLdb/cursors.py", line 330, in _query
    db.query(q)
  File "/home/bookofscotland/miniconda3/envs/BOS/lib/python3.8/site-packages/MySQLdb/connections.py", line 261, in query
    _mysql.connection.query(self, query)
django.db.utils.ProgrammingError: (1146, "Table 'aibos_django.bookscot_site_directory' doesn't exist")
Internal Server Error: /directory/19/
Traceback (most recent call last):
  File "/home/bookofscotland/miniconda3/envs/BOS/lib/python3.8/site-packages/django/db/backends/utils.py", line 89, in _execute
    return self.cursor.execute(sql, params)
  File "/home/bookofscotland/miniconda3/envs/BOS/lib/python3.8/site-packages/django/db/backends/mysql/base.py", line 75, in execute
    return self.cursor.execute(query, args)
  File "/home/bookofscotland/miniconda3/envs/BOS/lib/python3.8/site-packages/MySQLdb/cursors.py", line 179, in execute
    res = self._query(mogrified_query)
  File "/home/bookofscotland/miniconda3/envs/BOS/lib/python3.8/site-packages/MySQLdb/cursors.py", line 330, in _query
    db.query(q)
  File "/home/bookofscotland/miniconda3/envs/BOS/lib/python3.8/site-packages/MySQLdb/connections.py", line 261, in query
    _mysql.connection.query(self, query)
MySQLdb.ProgrammingError: (1146, "Table 'aibos_django.bookscot_site_directory' doesn't exist")

The above exception was the direct cause of the following exception:

Traceback (most recent call last):
  File "/home/bookofscotland/miniconda3/envs/BOS/lib/python3.8/site-packages/asgiref/sync.py", line 534, in thread_handler
    raise exc_info[1]
  File "/home/bookofscotland/miniconda3/envs/BOS/lib/python3.8/site-packages/django/core/handlers/exception.py", line 42, in inner
    response = await get_response(request)
  File "/home/bookofscotland/miniconda3/envs/BOS/lib/python3.8/site-packages/django/core/handlers/base.py", line 253, in _get_response_async
    response = await wrapped_callback(
  File "/home/bookofscotland/miniconda3/envs/BOS/lib/python3.8/site-packages/asgiref/sync.py", line 479, in __call__
    ret: _R = await loop.run_in_executor(
  File "/home/bookofscotland/miniconda3/envs/BOS/lib/python3.8/concurrent/futures/thread.py", line 57, in run
    result = self.fn(*self.args, **self.kwargs)
  File "/home/bookofscotland/miniconda3/envs/BOS/lib/python3.8/site-packages/asgiref/sync.py", line 538, in thread_handler
    return func(*args, **kwargs)
  File "/var/www/bookscot/public_site/views.py", line 70, in directory_main_view
    directory = get_object_or_404(Directory, id=directory_id)
  File "/home/bookofscotland/miniconda3/envs/BOS/lib/python3.8/site-packages/django/shortcuts.py", line 85, in get_object_or_404
    return queryset.get(*args, **kwargs)
  File "/home/bookofscotland/miniconda3/envs/BOS/lib/python3.8/site-packages/django/db/models/query.py", line 646, in get
    num = len(clone)
  File "/home/bookofscotland/miniconda3/envs/BOS/lib/python3.8/site-packages/django/db/models/query.py", line 376, in __len__
    self._fetch_all()
  File "/home/bookofscotland/miniconda3/envs/BOS/lib/python3.8/site-packages/django/db/models/query.py", line 1866, in _fetch_all
    self._result_cache = list(self._iterable_class(self))
  File "/home/bookofscotland/miniconda3/envs/BOS/lib/python3.8/site-packages/django/db/models/query.py", line 87, in __iter__
    results = compiler.execute_sql(
  File "/home/bookofscotland/miniconda3/envs/BOS/lib/python3.8/site-packages/django/db/models/sql/compiler.py", line 1395, in execute_sql
    cursor.execute(sql, params)
  File "/home/bookofscotland/miniconda3/envs/BOS/lib/python3.8/site-packages/django/db/backends/utils.py", line 67, in execute
    return self._execute_with_wrappers(
  File "/home/bookofscotland/miniconda3/envs/BOS/lib/python3.8/site-packages/django/db/backends/utils.py", line 80, in _execute_with_wrappers
    return executor(sql, params, many, context)
  File "/home/bookofscotland/miniconda3/envs/BOS/lib/python3.8/site-packages/django/db/backends/utils.py", line 89, in _execute
    return self.cursor.execute(sql, params)
  File "/home/bookofscotland/miniconda3/envs/BOS/lib/python3.8/site-packages/django/db/utils.py", line 91, in __exit__
    raise dj_exc_value.with_traceback(traceback) from exc_value
  File "/home/bookofscotland/miniconda3/envs/BOS/lib/python3.8/site-packages/django/db/backends/utils.py", line 89, in _execute
    return self.cursor.execute(sql, params)
  File "/home/bookofscotland/miniconda3/envs/BOS/lib/python3.8/site-packages/django/db/backends/mysql/base.py", line 75, in execute
    return self.cursor.execute(query, args)
  File "/home/bookofscotland/miniconda3/envs/BOS/lib/python3.8/site-packages/MySQLdb/cursors.py", line 179, in execute
    res = self._query(mogrified_query)
  File "/home/bookofscotland/miniconda3/envs/BOS/lib/python3.8/site-packages/MySQLdb/cursors.py", line 330, in _query
    db.query(q)
  File "/home/bookofscotland/miniconda3/envs/BOS/lib/python3.8/site-packages/MySQLdb/connections.py", line 261, in query
    _mysql.connection.query(self, query)
django.db.utils.ProgrammingError: (1146, "Table 'aibos_django.bookscot_site_directory' doesn't exist")
Internal Server Error: /directory/22/
Traceback (most recent call last):
  File "/home/bookofscotland/miniconda3/envs/BOS/lib/python3.8/site-packages/django/db/backends/utils.py", line 89, in _execute
    return self.cursor.execute(sql, params)
  File "/home/bookofscotland/miniconda3/envs/BOS/lib/python3.8/site-packages/django/db/backends/mysql/base.py", line 75, in execute
    return self.cursor.execute(query, args)
  File "/home/bookofscotland/miniconda3/envs/BOS/lib/python3.8/site-packages/MySQLdb/cursors.py", line 179, in execute
    res = self._query(mogrified_query)
  File "/home/bookofscotland/miniconda3/envs/BOS/lib/python3.8/site-packages/MySQLdb/cursors.py", line 330, in _query
    db.query(q)
  File "/home/bookofscotland/miniconda3/envs/BOS/lib/python3.8/site-packages/MySQLdb/connections.py", line 261, in query
    _mysql.connection.query(self, query)
MySQLdb.ProgrammingError: (1146, "Table 'aibos_django.bookscot_site_directory' doesn't exist")

The above exception was the direct cause of the following exception:

Traceback (most recent call last):
  File "/home/bookofscotland/miniconda3/envs/BOS/lib/python3.8/site-packages/asgiref/sync.py", line 534, in thread_handler
    raise exc_info[1]
  File "/home/bookofscotland/miniconda3/envs/BOS/lib/python3.8/site-packages/django/core/handlers/exception.py", line 42, in inner
    response = await get_response(request)
  File "/home/bookofscotland/miniconda3/envs/BOS/lib/python3.8/site-packages/django/core/handlers/base.py", line 253, in _get_response_async
    response = await wrapped_callback(
  File "/home/bookofscotland/miniconda3/envs/BOS/lib/python3.8/site-packages/asgiref/sync.py", line 479, in __call__
    ret: _R = await loop.run_in_executor(
  File "/home/bookofscotland/miniconda3/envs/BOS/lib/python3.8/concurrent/futures/thread.py", line 57, in run
    result = self.fn(*self.args, **self.kwargs)
  File "/home/bookofscotland/miniconda3/envs/BOS/lib/python3.8/site-packages/asgiref/sync.py", line 538, in thread_handler
    return func(*args, **kwargs)
  File "/var/www/bookscot/public_site/views.py", line 70, in directory_main_view
    directory = get_object_or_404(Directory, id=directory_id)
  File "/home/bookofscotland/miniconda3/envs/BOS/lib/python3.8/site-packages/django/shortcuts.py", line 85, in get_object_or_404
    return queryset.get(*args, **kwargs)
  File "/home/bookofscotland/miniconda3/envs/BOS/lib/python3.8/site-packages/django/db/models/query.py", line 646, in get
    num = len(clone)
  File "/home/bookofscotland/miniconda3/envs/BOS/lib/python3.8/site-packages/django/db/models/query.py", line 376, in __len__
    self._fetch_all()
  File "/home/bookofscotland/miniconda3/envs/BOS/lib/python3.8/site-packages/django/db/models/query.py", line 1866, in _fetch_all
    self._result_cache = list(self._iterable_class(self))
  File "/home/bookofscotland/miniconda3/envs/BOS/lib/python3.8/site-packages/django/db/models/query.py", line 87, in __iter__
    results = compiler.execute_sql(
  File "/home/bookofscotland/miniconda3/envs/BOS/lib/python3.8/site-packages/django/db/models/sql/compiler.py", line 1395, in execute_sql
    cursor.execute(sql, params)
  File "/home/bookofscotland/miniconda3/envs/BOS/lib/python3.8/site-packages/django/db/backends/utils.py", line 67, in execute
    return self._execute_with_wrappers(
  File "/home/bookofscotland/miniconda3/envs/BOS/lib/python3.8/site-packages/django/db/backends/utils.py", line 80, in _execute_with_wrappers
    return executor(sql, params, many, context)
  File "/home/bookofscotland/miniconda3/envs/BOS/lib/python3.8/site-packages/django/db/backends/utils.py", line 89, in _execute
    return self.cursor.execute(sql, params)
  File "/home/bookofscotland/miniconda3/envs/BOS/lib/python3.8/site-packages/django/db/utils.py", line 91, in __exit__
    raise dj_exc_value.with_traceback(traceback) from exc_value
  File "/home/bookofscotland/miniconda3/envs/BOS/lib/python3.8/site-packages/django/db/backends/utils.py", line 89, in _execute
    return self.cursor.execute(sql, params)
  File "/home/bookofscotland/miniconda3/envs/BOS/lib/python3.8/site-packages/django/db/backends/mysql/base.py", line 75, in execute
    return self.cursor.execute(query, args)
  File "/home/bookofscotland/miniconda3/envs/BOS/lib/python3.8/site-packages/MySQLdb/cursors.py", line 179, in execute
    res = self._query(mogrified_query)
  File "/home/bookofscotland/miniconda3/envs/BOS/lib/python3.8/site-packages/MySQLdb/cursors.py", line 330, in _query
    db.query(q)
  File "/home/bookofscotland/miniconda3/envs/BOS/lib/python3.8/site-packages/MySQLdb/connections.py", line 261, in query
    _mysql.connection.query(self, query)
django.db.utils.ProgrammingError: (1146, "Table 'aibos_django.bookscot_site_directory' doesn't exist")
Internal Server Error: /directory/17/
Traceback (most recent call last):
  File "/home/bookofscotland/miniconda3/envs/BOS/lib/python3.8/site-packages/django/db/backends/utils.py", line 89, in _execute
    return self.cursor.execute(sql, params)
  File "/home/bookofscotland/miniconda3/envs/BOS/lib/python3.8/site-packages/django/db/backends/mysql/base.py", line 75, in execute
    return self.cursor.execute(query, args)
  File "/home/bookofscotland/miniconda3/envs/BOS/lib/python3.8/site-packages/MySQLdb/cursors.py", line 179, in execute
    res = self._query(mogrified_query)
  File "/home/bookofscotland/miniconda3/envs/BOS/lib/python3.8/site-packages/MySQLdb/cursors.py", line 330, in _query
    db.query(q)
  File "/home/bookofscotland/miniconda3/envs/BOS/lib/python3.8/site-packages/MySQLdb/connections.py", line 261, in query
    _mysql.connection.query(self, query)
MySQLdb.ProgrammingError: (1146, "Table 'aibos_django.bookscot_site_directory' doesn't exist")

The above exception was the direct cause of the following exception:

Traceback (most recent call last):
  File "/home/bookofscotland/miniconda3/envs/BOS/lib/python3.8/site-packages/asgiref/sync.py", line 534, in thread_handler
    raise exc_info[1]
  File "/home/bookofscotland/miniconda3/envs/BOS/lib/python3.8/site-packages/django/core/handlers/exception.py", line 42, in inner
    response = await get_response(request)
  File "/home/bookofscotland/miniconda3/envs/BOS/lib/python3.8/site-packages/django/core/handlers/base.py", line 253, in _get_response_async
    response = await wrapped_callback(
  File "/home/bookofscotland/miniconda3/envs/BOS/lib/python3.8/site-packages/asgiref/sync.py", line 479, in __call__
    ret: _R = await loop.run_in_executor(
  File "/home/bookofscotland/miniconda3/envs/BOS/lib/python3.8/concurrent/futures/thread.py", line 57, in run
    result = self.fn(*self.args, **self.kwargs)
  File "/home/bookofscotland/miniconda3/envs/BOS/lib/python3.8/site-packages/asgiref/sync.py", line 538, in thread_handler
    return func(*args, **kwargs)
  File "/var/www/bookscot/public_site/views.py", line 70, in directory_main_view
    directory = get_object_or_404(Directory, id=directory_id)
  File "/home/bookofscotland/miniconda3/envs/BOS/lib/python3.8/site-packages/django/shortcuts.py", line 85, in get_object_or_404
    return queryset.get(*args, **kwargs)
  File "/home/bookofscotland/miniconda3/envs/BOS/lib/python3.8/site-packages/django/db/models/query.py", line 646, in get
    num = len(clone)
  File "/home/bookofscotland/miniconda3/envs/BOS/lib/python3.8/site-packages/django/db/models/query.py", line 376, in __len__
    self._fetch_all()
  File "/home/bookofscotland/miniconda3/envs/BOS/lib/python3.8/site-packages/django/db/models/query.py", line 1866, in _fetch_all
    self._result_cache = list(self._iterable_class(self))
  File "/home/bookofscotland/miniconda3/envs/BOS/lib/python3.8/site-packages/django/db/models/query.py", line 87, in __iter__
    results = compiler.execute_sql(
  File "/home/bookofscotland/miniconda3/envs/BOS/lib/python3.8/site-packages/django/db/models/sql/compiler.py", line 1395, in execute_sql
    cursor.execute(sql, params)
  File "/home/bookofscotland/miniconda3/envs/BOS/lib/python3.8/site-packages/django/db/backends/utils.py", line 67, in execute
    return self._execute_with_wrappers(
  File "/home/bookofscotland/miniconda3/envs/BOS/lib/python3.8/site-packages/django/db/backends/utils.py", line 80, in _execute_with_wrappers
    return executor(sql, params, many, context)
  File "/home/bookofscotland/miniconda3/envs/BOS/lib/python3.8/site-packages/django/db/backends/utils.py", line 89, in _execute
    return self.cursor.execute(sql, params)
  File "/home/bookofscotland/miniconda3/envs/BOS/lib/python3.8/site-packages/django/db/utils.py", line 91, in __exit__
    raise dj_exc_value.with_traceback(traceback) from exc_value
  File "/home/bookofscotland/miniconda3/envs/BOS/lib/python3.8/site-packages/django/db/backends/utils.py", line 89, in _execute
    return self.cursor.execute(sql, params)
  File "/home/bookofscotland/miniconda3/envs/BOS/lib/python3.8/site-packages/django/db/backends/mysql/base.py", line 75, in execute
    return self.cursor.execute(query, args)
  File "/home/bookofscotland/miniconda3/envs/BOS/lib/python3.8/site-packages/MySQLdb/cursors.py", line 179, in execute
    res = self._query(mogrified_query)
  File "/home/bookofscotland/miniconda3/envs/BOS/lib/python3.8/site-packages/MySQLdb/cursors.py", line 330, in _query
    db.query(q)
  File "/home/bookofscotland/miniconda3/envs/BOS/lib/python3.8/site-packages/MySQLdb/connections.py", line 261, in query
    _mysql.connection.query(self, query)
django.db.utils.ProgrammingError: (1146, "Table 'aibos_django.bookscot_site_directory' doesn't exist")
Internal Server Error: /directory/1/
Traceback (most recent call last):
  File "/home/bookofscotland/miniconda3/envs/BOS/lib/python3.8/site-packages/django/db/backends/utils.py", line 89, in _execute
    return self.cursor.execute(sql, params)
  File "/home/bookofscotland/miniconda3/envs/BOS/lib/python3.8/site-packages/django/db/backends/mysql/base.py", line 75, in execute
    return self.cursor.execute(query, args)
  File "/home/bookofscotland/miniconda3/envs/BOS/lib/python3.8/site-packages/MySQLdb/cursors.py", line 179, in execute
    res = self._query(mogrified_query)
  File "/home/bookofscotland/miniconda3/envs/BOS/lib/python3.8/site-packages/MySQLdb/cursors.py", line 330, in _query
    db.query(q)
  File "/home/bookofscotland/miniconda3/envs/BOS/lib/python3.8/site-packages/MySQLdb/connections.py", line 261, in query
    _mysql.connection.query(self, query)
MySQLdb.ProgrammingError: (1146, "Table 'aibos_django.bookscot_site_directory' doesn't exist")

The above exception was the direct cause of the following exception:

Traceback (most recent call last):
  File "/home/bookofscotland/miniconda3/envs/BOS/lib/python3.8/site-packages/asgiref/sync.py", line 534, in thread_handler
    raise exc_info[1]
  File "/home/bookofscotland/miniconda3/envs/BOS/lib/python3.8/site-packages/django/core/handlers/exception.py", line 42, in inner
    response = await get_response(request)
  File "/home/bookofscotland/miniconda3/envs/BOS/lib/python3.8/site-packages/django/core/handlers/base.py", line 253, in _get_response_async
    response = await wrapped_callback(
  File "/home/bookofscotland/miniconda3/envs/BOS/lib/python3.8/site-packages/asgiref/sync.py", line 479, in __call__
    ret: _R = await loop.run_in_executor(
  File "/home/bookofscotland/miniconda3/envs/BOS/lib/python3.8/concurrent/futures/thread.py", line 57, in run
    result = self.fn(*self.args, **self.kwargs)
  File "/home/bookofscotland/miniconda3/envs/BOS/lib/python3.8/site-packages/asgiref/sync.py", line 538, in thread_handler
    return func(*args, **kwargs)
  File "/var/www/bookscot/public_site/views.py", line 70, in directory_main_view
    directory = get_object_or_404(Directory, id=directory_id)
  File "/home/bookofscotland/miniconda3/envs/BOS/lib/python3.8/site-packages/django/shortcuts.py", line 85, in get_object_or_404
    return queryset.get(*args, **kwargs)
  File "/home/bookofscotland/miniconda3/envs/BOS/lib/python3.8/site-packages/django/db/models/query.py", line 646, in get
    num = len(clone)
  File "/home/bookofscotland/miniconda3/envs/BOS/lib/python3.8/site-packages/django/db/models/query.py", line 376, in __len__
    self._fetch_all()
  File "/home/bookofscotland/miniconda3/envs/BOS/lib/python3.8/site-packages/django/db/models/query.py", line 1866, in _fetch_all
    self._result_cache = list(self._iterable_class(self))
  File "/home/bookofscotland/miniconda3/envs/BOS/lib/python3.8/site-packages/django/db/models/query.py", line 87, in __iter__
    results = compiler.execute_sql(
  File "/home/bookofscotland/miniconda3/envs/BOS/lib/python3.8/site-packages/django/db/models/sql/compiler.py", line 1395, in execute_sql
    cursor.execute(sql, params)
  File "/home/bookofscotland/miniconda3/envs/BOS/lib/python3.8/site-packages/django/db/backends/utils.py", line 67, in execute
    return self._execute_with_wrappers(
  File "/home/bookofscotland/miniconda3/envs/BOS/lib/python3.8/site-packages/django/db/backends/utils.py", line 80, in _execute_with_wrappers
    return executor(sql, params, many, context)
  File "/home/bookofscotland/miniconda3/envs/BOS/lib/python3.8/site-packages/django/db/backends/utils.py", line 89, in _execute
    return self.cursor.execute(sql, params)
  File "/home/bookofscotland/miniconda3/envs/BOS/lib/python3.8/site-packages/django/db/utils.py", line 91, in __exit__
    raise dj_exc_value.with_traceback(traceback) from exc_value
  File "/home/bookofscotland/miniconda3/envs/BOS/lib/python3.8/site-packages/django/db/backends/utils.py", line 89, in _execute
    return self.cursor.execute(sql, params)
  File "/home/bookofscotland/miniconda3/envs/BOS/lib/python3.8/site-packages/django/db/backends/mysql/base.py", line 75, in execute
    return self.cursor.execute(query, args)
  File "/home/bookofscotland/miniconda3/envs/BOS/lib/python3.8/site-packages/MySQLdb/cursors.py", line 179, in execute
    res = self._query(mogrified_query)
  File "/home/bookofscotland/miniconda3/envs/BOS/lib/python3.8/site-packages/MySQLdb/cursors.py", line 330, in _query
    db.query(q)
  File "/home/bookofscotland/miniconda3/envs/BOS/lib/python3.8/site-packages/MySQLdb/connections.py", line 261, in query
    _mysql.connection.query(self, query)
django.db.utils.ProgrammingError: (1146, "Table 'aibos_django.bookscot_site_directory' doesn't exist")
Internal Server Error: /directory/2/
Traceback (most recent call last):
  File "/home/bookofscotland/miniconda3/envs/BOS/lib/python3.8/site-packages/django/db/backends/utils.py", line 89, in _execute
    return self.cursor.execute(sql, params)
  File "/home/bookofscotland/miniconda3/envs/BOS/lib/python3.8/site-packages/django/db/backends/mysql/base.py", line 75, in execute
    return self.cursor.execute(query, args)
  File "/home/bookofscotland/miniconda3/envs/BOS/lib/python3.8/site-packages/MySQLdb/cursors.py", line 179, in execute
    res = self._query(mogrified_query)
  File "/home/bookofscotland/miniconda3/envs/BOS/lib/python3.8/site-packages/MySQLdb/cursors.py", line 330, in _query
    db.query(q)
  File "/home/bookofscotland/miniconda3/envs/BOS/lib/python3.8/site-packages/MySQLdb/connections.py", line 261, in query
    _mysql.connection.query(self, query)
MySQLdb.ProgrammingError: (1146, "Table 'aibos_django.bookscot_site_directory' doesn't exist")

The above exception was the direct cause of the following exception:

Traceback (most recent call last):
  File "/home/bookofscotland/miniconda3/envs/BOS/lib/python3.8/site-packages/asgiref/sync.py", line 534, in thread_handler
    raise exc_info[1]
  File "/home/bookofscotland/miniconda3/envs/BOS/lib/python3.8/site-packages/django/core/handlers/exception.py", line 42, in inner
    response = await get_response(request)
  File "/home/bookofscotland/miniconda3/envs/BOS/lib/python3.8/site-packages/django/core/handlers/base.py", line 253, in _get_response_async
    response = await wrapped_callback(
  File "/home/bookofscotland/miniconda3/envs/BOS/lib/python3.8/site-packages/asgiref/sync.py", line 479, in __call__
    ret: _R = await loop.run_in_executor(
  File "/home/bookofscotland/miniconda3/envs/BOS/lib/python3.8/concurrent/futures/thread.py", line 57, in run
    result = self.fn(*self.args, **self.kwargs)
  File "/home/bookofscotland/miniconda3/envs/BOS/lib/python3.8/site-packages/asgiref/sync.py", line 538, in thread_handler
    return func(*args, **kwargs)
  File "/var/www/bookscot/public_site/views.py", line 70, in directory_main_view
    directory = get_object_or_404(Directory, id=directory_id)
  File "/home/bookofscotland/miniconda3/envs/BOS/lib/python3.8/site-packages/django/shortcuts.py", line 85, in get_object_or_404
    return queryset.get(*args, **kwargs)
  File "/home/bookofscotland/miniconda3/envs/BOS/lib/python3.8/site-packages/django/db/models/query.py", line 646, in get
    num = len(clone)
  File "/home/bookofscotland/miniconda3/envs/BOS/lib/python3.8/site-packages/django/db/models/query.py", line 376, in __len__
    self._fetch_all()
  File "/home/bookofscotland/miniconda3/envs/BOS/lib/python3.8/site-packages/django/db/models/query.py", line 1866, in _fetch_all
    self._result_cache = list(self._iterable_class(self))
  File "/home/bookofscotland/miniconda3/envs/BOS/lib/python3.8/site-packages/django/db/models/query.py", line 87, in __iter__
    results = compiler.execute_sql(
  File "/home/bookofscotland/miniconda3/envs/BOS/lib/python3.8/site-packages/django/db/models/sql/compiler.py", line 1395, in execute_sql
    cursor.execute(sql, params)
  File "/home/bookofscotland/miniconda3/envs/BOS/lib/python3.8/site-packages/django/db/backends/utils.py", line 67, in execute
    return self._execute_with_wrappers(
  File "/home/bookofscotland/miniconda3/envs/BOS/lib/python3.8/site-packages/django/db/backends/utils.py", line 80, in _execute_with_wrappers
    return executor(sql, params, many, context)
  File "/home/bookofscotland/miniconda3/envs/BOS/lib/python3.8/site-packages/django/db/backends/utils.py", line 89, in _execute
    return self.cursor.execute(sql, params)
  File "/home/bookofscotland/miniconda3/envs/BOS/lib/python3.8/site-packages/django/db/utils.py", line 91, in __exit__
    raise dj_exc_value.with_traceback(traceback) from exc_value
  File "/home/bookofscotland/miniconda3/envs/BOS/lib/python3.8/site-packages/django/db/backends/utils.py", line 89, in _execute
    return self.cursor.execute(sql, params)
  File "/home/bookofscotland/miniconda3/envs/BOS/lib/python3.8/site-packages/django/db/backends/mysql/base.py", line 75, in execute
    return self.cursor.execute(query, args)
  File "/home/bookofscotland/miniconda3/envs/BOS/lib/python3.8/site-packages/MySQLdb/cursors.py", line 179, in execute
    res = self._query(mogrified_query)
  File "/home/bookofscotland/miniconda3/envs/BOS/lib/python3.8/site-packages/MySQLdb/cursors.py", line 330, in _query
    db.query(q)
  File "/home/bookofscotland/miniconda3/envs/BOS/lib/python3.8/site-packages/MySQLdb/connections.py", line 261, in query
    _mysql.connection.query(self, query)
django.db.utils.ProgrammingError: (1146, "Table 'aibos_django.bookscot_site_directory' doesn't exist")
Internal Server Error: /directory/3/
Traceback (most recent call last):
  File "/home/bookofscotland/miniconda3/envs/BOS/lib/python3.8/site-packages/django/db/backends/utils.py", line 89, in _execute
    return self.cursor.execute(sql, params)
  File "/home/bookofscotland/miniconda3/envs/BOS/lib/python3.8/site-packages/django/db/backends/mysql/base.py", line 75, in execute
    return self.cursor.execute(query, args)
  File "/home/bookofscotland/miniconda3/envs/BOS/lib/python3.8/site-packages/MySQLdb/cursors.py", line 179, in execute
    res = self._query(mogrified_query)
  File "/home/bookofscotland/miniconda3/envs/BOS/lib/python3.8/site-packages/MySQLdb/cursors.py", line 330, in _query
    db.query(q)
  File "/home/bookofscotland/miniconda3/envs/BOS/lib/python3.8/site-packages/MySQLdb/connections.py", line 261, in query
    _mysql.connection.query(self, query)
MySQLdb.ProgrammingError: (1146, "Table 'aibos_django.bookscot_site_directory' doesn't exist")

The above exception was the direct cause of the following exception:

Traceback (most recent call last):
  File "/home/bookofscotland/miniconda3/envs/BOS/lib/python3.8/site-packages/asgiref/sync.py", line 534, in thread_handler
    raise exc_info[1]
  File "/home/bookofscotland/miniconda3/envs/BOS/lib/python3.8/site-packages/django/core/handlers/exception.py", line 42, in inner
    response = await get_response(request)
  File "/home/bookofscotland/miniconda3/envs/BOS/lib/python3.8/site-packages/django/core/handlers/base.py", line 253, in _get_response_async
    response = await wrapped_callback(
  File "/home/bookofscotland/miniconda3/envs/BOS/lib/python3.8/site-packages/asgiref/sync.py", line 479, in __call__
    ret: _R = await loop.run_in_executor(
  File "/home/bookofscotland/miniconda3/envs/BOS/lib/python3.8/concurrent/futures/thread.py", line 57, in run
    result = self.fn(*self.args, **self.kwargs)
  File "/home/bookofscotland/miniconda3/envs/BOS/lib/python3.8/site-packages/asgiref/sync.py", line 538, in thread_handler
    return func(*args, **kwargs)
  File "/var/www/bookscot/public_site/views.py", line 70, in directory_main_view
    directory = get_object_or_404(Directory, id=directory_id)
  File "/home/bookofscotland/miniconda3/envs/BOS/lib/python3.8/site-packages/django/shortcuts.py", line 85, in get_object_or_404
    return queryset.get(*args, **kwargs)
  File "/home/bookofscotland/miniconda3/envs/BOS/lib/python3.8/site-packages/django/db/models/query.py", line 646, in get
    num = len(clone)
  File "/home/bookofscotland/miniconda3/envs/BOS/lib/python3.8/site-packages/django/db/models/query.py", line 376, in __len__
    self._fetch_all()
  File "/home/bookofscotland/miniconda3/envs/BOS/lib/python3.8/site-packages/django/db/models/query.py", line 1866, in _fetch_all
    self._result_cache = list(self._iterable_class(self))
  File "/home/bookofscotland/miniconda3/envs/BOS/lib/python3.8/site-packages/django/db/models/query.py", line 87, in __iter__
    results = compiler.execute_sql(
  File "/home/bookofscotland/miniconda3/envs/BOS/lib/python3.8/site-packages/django/db/models/sql/compiler.py", line 1395, in execute_sql
    cursor.execute(sql, params)
  File "/home/bookofscotland/miniconda3/envs/BOS/lib/python3.8/site-packages/django/db/backends/utils.py", line 67, in execute
    return self._execute_with_wrappers(
  File "/home/bookofscotland/miniconda3/envs/BOS/lib/python3.8/site-packages/django/db/backends/utils.py", line 80, in _execute_with_wrappers
    return executor(sql, params, many, context)
  File "/home/bookofscotland/miniconda3/envs/BOS/lib/python3.8/site-packages/django/db/backends/utils.py", line 89, in _execute
    return self.cursor.execute(sql, params)
  File "/home/bookofscotland/miniconda3/envs/BOS/lib/python3.8/site-packages/django/db/utils.py", line 91, in __exit__
    raise dj_exc_value.with_traceback(traceback) from exc_value
  File "/home/bookofscotland/miniconda3/envs/BOS/lib/python3.8/site-packages/django/db/backends/utils.py", line 89, in _execute
    return self.cursor.execute(sql, params)
  File "/home/bookofscotland/miniconda3/envs/BOS/lib/python3.8/site-packages/django/db/backends/mysql/base.py", line 75, in execute
    return self.cursor.execute(query, args)
  File "/home/bookofscotland/miniconda3/envs/BOS/lib/python3.8/site-packages/MySQLdb/cursors.py", line 179, in execute
    res = self._query(mogrified_query)
  File "/home/bookofscotland/miniconda3/envs/BOS/lib/python3.8/site-packages/MySQLdb/cursors.py", line 330, in _query
    db.query(q)
  File "/home/bookofscotland/miniconda3/envs/BOS/lib/python3.8/site-packages/MySQLdb/connections.py", line 261, in query
    _mysql.connection.query(self, query)
django.db.utils.ProgrammingError: (1146, "Table 'aibos_django.bookscot_site_directory' doesn't exist")
Internal Server Error: /directory/4/
Traceback (most recent call last):
  File "/home/bookofscotland/miniconda3/envs/BOS/lib/python3.8/site-packages/django/db/backends/utils.py", line 89, in _execute
    return self.cursor.execute(sql, params)
  File "/home/bookofscotland/miniconda3/envs/BOS/lib/python3.8/site-packages/django/db/backends/mysql/base.py", line 75, in execute
    return self.cursor.execute(query, args)
  File "/home/bookofscotland/miniconda3/envs/BOS/lib/python3.8/site-packages/MySQLdb/cursors.py", line 179, in execute
    res = self._query(mogrified_query)
  File "/home/bookofscotland/miniconda3/envs/BOS/lib/python3.8/site-packages/MySQLdb/cursors.py", line 330, in _query
    db.query(q)
  File "/home/bookofscotland/miniconda3/envs/BOS/lib/python3.8/site-packages/MySQLdb/connections.py", line 261, in query
    _mysql.connection.query(self, query)
MySQLdb.ProgrammingError: (1146, "Table 'aibos_django.bookscot_site_directory' doesn't exist")

The above exception was the direct cause of the following exception:

Traceback (most recent call last):
  File "/home/bookofscotland/miniconda3/envs/BOS/lib/python3.8/site-packages/asgiref/sync.py", line 534, in thread_handler
    raise exc_info[1]
  File "/home/bookofscotland/miniconda3/envs/BOS/lib/python3.8/site-packages/django/core/handlers/exception.py", line 42, in inner
    response = await get_response(request)
  File "/home/bookofscotland/miniconda3/envs/BOS/lib/python3.8/site-packages/django/core/handlers/base.py", line 253, in _get_response_async
    response = await wrapped_callback(
  File "/home/bookofscotland/miniconda3/envs/BOS/lib/python3.8/site-packages/asgiref/sync.py", line 479, in __call__
    ret: _R = await loop.run_in_executor(
  File "/home/bookofscotland/miniconda3/envs/BOS/lib/python3.8/concurrent/futures/thread.py", line 57, in run
    result = self.fn(*self.args, **self.kwargs)
  File "/home/bookofscotland/miniconda3/envs/BOS/lib/python3.8/site-packages/asgiref/sync.py", line 538, in thread_handler
    return func(*args, **kwargs)
  File "/var/www/bookscot/public_site/views.py", line 70, in directory_main_view
    directory = get_object_or_404(Directory, id=directory_id)
  File "/home/bookofscotland/miniconda3/envs/BOS/lib/python3.8/site-packages/django/shortcuts.py", line 85, in get_object_or_404
    return queryset.get(*args, **kwargs)
  File "/home/bookofscotland/miniconda3/envs/BOS/lib/python3.8/site-packages/django/db/models/query.py", line 646, in get
    num = len(clone)
  File "/home/bookofscotland/miniconda3/envs/BOS/lib/python3.8/site-packages/django/db/models/query.py", line 376, in __len__
    self._fetch_all()
  File "/home/bookofscotland/miniconda3/envs/BOS/lib/python3.8/site-packages/django/db/models/query.py", line 1866, in _fetch_all
    self._result_cache = list(self._iterable_class(self))
  File "/home/bookofscotland/miniconda3/envs/BOS/lib/python3.8/site-packages/django/db/models/query.py", line 87, in __iter__
    results = compiler.execute_sql(
  File "/home/bookofscotland/miniconda3/envs/BOS/lib/python3.8/site-packages/django/db/models/sql/compiler.py", line 1395, in execute_sql
    cursor.execute(sql, params)
  File "/home/bookofscotland/miniconda3/envs/BOS/lib/python3.8/site-packages/django/db/backends/utils.py", line 67, in execute
    return self._execute_with_wrappers(
  File "/home/bookofscotland/miniconda3/envs/BOS/lib/python3.8/site-packages/django/db/backends/utils.py", line 80, in _execute_with_wrappers
    return executor(sql, params, many, context)
  File "/home/bookofscotland/miniconda3/envs/BOS/lib/python3.8/site-packages/django/db/backends/utils.py", line 89, in _execute
    return self.cursor.execute(sql, params)
  File "/home/bookofscotland/miniconda3/envs/BOS/lib/python3.8/site-packages/django/db/utils.py", line 91, in __exit__
    raise dj_exc_value.with_traceback(traceback) from exc_value
  File "/home/bookofscotland/miniconda3/envs/BOS/lib/python3.8/site-packages/django/db/backends/utils.py", line 89, in _execute
    return self.cursor.execute(sql, params)
  File "/home/bookofscotland/miniconda3/envs/BOS/lib/python3.8/site-packages/django/db/backends/mysql/base.py", line 75, in execute
    return self.cursor.execute(query, args)
  File "/home/bookofscotland/miniconda3/envs/BOS/lib/python3.8/site-packages/MySQLdb/cursors.py", line 179, in execute
    res = self._query(mogrified_query)
  File "/home/bookofscotland/miniconda3/envs/BOS/lib/python3.8/site-packages/MySQLdb/cursors.py", line 330, in _query
    db.query(q)
  File "/home/bookofscotland/miniconda3/envs/BOS/lib/python3.8/site-packages/MySQLdb/connections.py", line 261, in query
    _mysql.connection.query(self, query)
django.db.utils.ProgrammingError: (1146, "Table 'aibos_django.bookscot_site_directory' doesn't exist")
Internal Server Error: /directory/41/
Traceback (most recent call last):
  File "/home/bookofscotland/miniconda3/envs/BOS/lib/python3.8/site-packages/django/db/backends/utils.py", line 89, in _execute
    return self.cursor.execute(sql, params)
  File "/home/bookofscotland/miniconda3/envs/BOS/lib/python3.8/site-packages/django/db/backends/mysql/base.py", line 75, in execute
    return self.cursor.execute(query, args)
  File "/home/bookofscotland/miniconda3/envs/BOS/lib/python3.8/site-packages/MySQLdb/cursors.py", line 179, in execute
    res = self._query(mogrified_query)
  File "/home/bookofscotland/miniconda3/envs/BOS/lib/python3.8/site-packages/MySQLdb/cursors.py", line 330, in _query
    db.query(q)
  File "/home/bookofscotland/miniconda3/envs/BOS/lib/python3.8/site-packages/MySQLdb/connections.py", line 261, in query
    _mysql.connection.query(self, query)
MySQLdb.ProgrammingError: (1146, "Table 'aibos_django.bookscot_site_directory' doesn't exist")

The above exception was the direct cause of the following exception:

Traceback (most recent call last):
  File "/home/bookofscotland/miniconda3/envs/BOS/lib/python3.8/site-packages/asgiref/sync.py", line 534, in thread_handler
    raise exc_info[1]
  File "/home/bookofscotland/miniconda3/envs/BOS/lib/python3.8/site-packages/django/core/handlers/exception.py", line 42, in inner
    response = await get_response(request)
  File "/home/bookofscotland/miniconda3/envs/BOS/lib/python3.8/site-packages/django/core/handlers/base.py", line 253, in _get_response_async
    response = await wrapped_callback(
  File "/home/bookofscotland/miniconda3/envs/BOS/lib/python3.8/site-packages/asgiref/sync.py", line 479, in __call__
    ret: _R = await loop.run_in_executor(
  File "/home/bookofscotland/miniconda3/envs/BOS/lib/python3.8/concurrent/futures/thread.py", line 57, in run
    result = self.fn(*self.args, **self.kwargs)
  File "/home/bookofscotland/miniconda3/envs/BOS/lib/python3.8/site-packages/asgiref/sync.py", line 538, in thread_handler
    return func(*args, **kwargs)
  File "/var/www/bookscot/public_site/views.py", line 70, in directory_main_view
    directory = get_object_or_404(Directory, id=directory_id)
  File "/home/bookofscotland/miniconda3/envs/BOS/lib/python3.8/site-packages/django/shortcuts.py", line 85, in get_object_or_404
    return queryset.get(*args, **kwargs)
  File "/home/bookofscotland/miniconda3/envs/BOS/lib/python3.8/site-packages/django/db/models/query.py", line 646, in get
    num = len(clone)
  File "/home/bookofscotland/miniconda3/envs/BOS/lib/python3.8/site-packages/django/db/models/query.py", line 376, in __len__
    self._fetch_all()
  File "/home/bookofscotland/miniconda3/envs/BOS/lib/python3.8/site-packages/django/db/models/query.py", line 1866, in _fetch_all
    self._result_cache = list(self._iterable_class(self))
  File "/home/bookofscotland/miniconda3/envs/BOS/lib/python3.8/site-packages/django/db/models/query.py", line 87, in __iter__
    results = compiler.execute_sql(
  File "/home/bookofscotland/miniconda3/envs/BOS/lib/python3.8/site-packages/django/db/models/sql/compiler.py", line 1395, in execute_sql
    cursor.execute(sql, params)
  File "/home/bookofscotland/miniconda3/envs/BOS/lib/python3.8/site-packages/django/db/backends/utils.py", line 67, in execute
    return self._execute_with_wrappers(
  File "/home/bookofscotland/miniconda3/envs/BOS/lib/python3.8/site-packages/django/db/backends/utils.py", line 80, in _execute_with_wrappers
    return executor(sql, params, many, context)
  File "/home/bookofscotland/miniconda3/envs/BOS/lib/python3.8/site-packages/django/db/backends/utils.py", line 89, in _execute
    return self.cursor.execute(sql, params)
  File "/home/bookofscotland/miniconda3/envs/BOS/lib/python3.8/site-packages/django/db/utils.py", line 91, in __exit__
    raise dj_exc_value.with_traceback(traceback) from exc_value
  File "/home/bookofscotland/miniconda3/envs/BOS/lib/python3.8/site-packages/django/db/backends/utils.py", line 89, in _execute
    return self.cursor.execute(sql, params)
  File "/home/bookofscotland/miniconda3/envs/BOS/lib/python3.8/site-packages/django/db/backends/mysql/base.py", line 75, in execute
    return self.cursor.execute(query, args)
  File "/home/bookofscotland/miniconda3/envs/BOS/lib/python3.8/site-packages/MySQLdb/cursors.py", line 179, in execute
    res = self._query(mogrified_query)
  File "/home/bookofscotland/miniconda3/envs/BOS/lib/python3.8/site-packages/MySQLdb/cursors.py", line 330, in _query
    db.query(q)
  File "/home/bookofscotland/miniconda3/envs/BOS/lib/python3.8/site-packages/MySQLdb/connections.py", line 261, in query
    _mysql.connection.query(self, query)
django.db.utils.ProgrammingError: (1146, "Table 'aibos_django.bookscot_site_directory' doesn't exist")
Internal Server Error: /directory/38/
Traceback (most recent call last):
  File "/home/bookofscotland/miniconda3/envs/BOS/lib/python3.8/site-packages/django/db/backends/utils.py", line 89, in _execute
    return self.cursor.execute(sql, params)
  File "/home/bookofscotland/miniconda3/envs/BOS/lib/python3.8/site-packages/django/db/backends/mysql/base.py", line 75, in execute
    return self.cursor.execute(query, args)
  File "/home/bookofscotland/miniconda3/envs/BOS/lib/python3.8/site-packages/MySQLdb/cursors.py", line 179, in execute
    res = self._query(mogrified_query)
  File "/home/bookofscotland/miniconda3/envs/BOS/lib/python3.8/site-packages/MySQLdb/cursors.py", line 330, in _query
    db.query(q)
  File "/home/bookofscotland/miniconda3/envs/BOS/lib/python3.8/site-packages/MySQLdb/connections.py", line 261, in query
    _mysql.connection.query(self, query)
MySQLdb.ProgrammingError: (1146, "Table 'aibos_django.bookscot_site_directory' doesn't exist")

The above exception was the direct cause of the following exception:

Traceback (most recent call last):
  File "/home/bookofscotland/miniconda3/envs/BOS/lib/python3.8/site-packages/asgiref/sync.py", line 534, in thread_handler
    raise exc_info[1]
  File "/home/bookofscotland/miniconda3/envs/BOS/lib/python3.8/site-packages/django/core/handlers/exception.py", line 42, in inner
    response = await get_response(request)
  File "/home/bookofscotland/miniconda3/envs/BOS/lib/python3.8/site-packages/django/core/handlers/base.py", line 253, in _get_response_async
    response = await wrapped_callback(
  File "/home/bookofscotland/miniconda3/envs/BOS/lib/python3.8/site-packages/asgiref/sync.py", line 479, in __call__
    ret: _R = await loop.run_in_executor(
  File "/home/bookofscotland/miniconda3/envs/BOS/lib/python3.8/concurrent/futures/thread.py", line 57, in run
    result = self.fn(*self.args, **self.kwargs)
  File "/home/bookofscotland/miniconda3/envs/BOS/lib/python3.8/site-packages/asgiref/sync.py", line 538, in thread_handler
    return func(*args, **kwargs)
  File "/var/www/bookscot/public_site/views.py", line 70, in directory_main_view
    directory = get_object_or_404(Directory, id=directory_id)
  File "/home/bookofscotland/miniconda3/envs/BOS/lib/python3.8/site-packages/django/shortcuts.py", line 85, in get_object_or_404
    return queryset.get(*args, **kwargs)
  File "/home/bookofscotland/miniconda3/envs/BOS/lib/python3.8/site-packages/django/db/models/query.py", line 646, in get
    num = len(clone)
  File "/home/bookofscotland/miniconda3/envs/BOS/lib/python3.8/site-packages/django/db/models/query.py", line 376, in __len__
    self._fetch_all()
  File "/home/bookofscotland/miniconda3/envs/BOS/lib/python3.8/site-packages/django/db/models/query.py", line 1866, in _fetch_all
    self._result_cache = list(self._iterable_class(self))
  File "/home/bookofscotland/miniconda3/envs/BOS/lib/python3.8/site-packages/django/db/models/query.py", line 87, in __iter__
    results = compiler.execute_sql(
  File "/home/bookofscotland/miniconda3/envs/BOS/lib/python3.8/site-packages/django/db/models/sql/compiler.py", line 1395, in execute_sql
    cursor.execute(sql, params)
  File "/home/bookofscotland/miniconda3/envs/BOS/lib/python3.8/site-packages/django/db/backends/utils.py", line 67, in execute
    return self._execute_with_wrappers(
  File "/home/bookofscotland/miniconda3/envs/BOS/lib/python3.8/site-packages/django/db/backends/utils.py", line 80, in _execute_with_wrappers
    return executor(sql, params, many, context)
  File "/home/bookofscotland/miniconda3/envs/BOS/lib/python3.8/site-packages/django/db/backends/utils.py", line 89, in _execute
    return self.cursor.execute(sql, params)
  File "/home/bookofscotland/miniconda3/envs/BOS/lib/python3.8/site-packages/django/db/utils.py", line 91, in __exit__
    raise dj_exc_value.with_traceback(traceback) from exc_value
  File "/home/bookofscotland/miniconda3/envs/BOS/lib/python3.8/site-packages/django/db/backends/utils.py", line 89, in _execute
    return self.cursor.execute(sql, params)
  File "/home/bookofscotland/miniconda3/envs/BOS/lib/python3.8/site-packages/django/db/backends/mysql/base.py", line 75, in execute
    return self.cursor.execute(query, args)
  File "/home/bookofscotland/miniconda3/envs/BOS/lib/python3.8/site-packages/MySQLdb/cursors.py", line 179, in execute
    res = self._query(mogrified_query)
  File "/home/bookofscotland/miniconda3/envs/BOS/lib/python3.8/site-packages/MySQLdb/cursors.py", line 330, in _query
    db.query(q)
  File "/home/bookofscotland/miniconda3/envs/BOS/lib/python3.8/site-packages/MySQLdb/connections.py", line 261, in query
    _mysql.connection.query(self, query)
django.db.utils.ProgrammingError: (1146, "Table 'aibos_django.bookscot_site_directory' doesn't exist")
Internal Server Error: /directory/37/
Traceback (most recent call last):
  File "/home/bookofscotland/miniconda3/envs/BOS/lib/python3.8/site-packages/django/db/backends/utils.py", line 89, in _execute
    return self.cursor.execute(sql, params)
  File "/home/bookofscotland/miniconda3/envs/BOS/lib/python3.8/site-packages/django/db/backends/mysql/base.py", line 75, in execute
    return self.cursor.execute(query, args)
  File "/home/bookofscotland/miniconda3/envs/BOS/lib/python3.8/site-packages/MySQLdb/cursors.py", line 179, in execute
    res = self._query(mogrified_query)
  File "/home/bookofscotland/miniconda3/envs/BOS/lib/python3.8/site-packages/MySQLdb/cursors.py", line 330, in _query
    db.query(q)
  File "/home/bookofscotland/miniconda3/envs/BOS/lib/python3.8/site-packages/MySQLdb/connections.py", line 261, in query
    _mysql.connection.query(self, query)
MySQLdb.ProgrammingError: (1146, "Table 'aibos_django.bookscot_site_directory' doesn't exist")

The above exception was the direct cause of the following exception:

Traceback (most recent call last):
  File "/home/bookofscotland/miniconda3/envs/BOS/lib/python3.8/site-packages/asgiref/sync.py", line 534, in thread_handler
    raise exc_info[1]
  File "/home/bookofscotland/miniconda3/envs/BOS/lib/python3.8/site-packages/django/core/handlers/exception.py", line 42, in inner
    response = await get_response(request)
  File "/home/bookofscotland/miniconda3/envs/BOS/lib/python3.8/site-packages/django/core/handlers/base.py", line 253, in _get_response_async
    response = await wrapped_callback(
  File "/home/bookofscotland/miniconda3/envs/BOS/lib/python3.8/site-packages/asgiref/sync.py", line 479, in __call__
    ret: _R = await loop.run_in_executor(
  File "/home/bookofscotland/miniconda3/envs/BOS/lib/python3.8/concurrent/futures/thread.py", line 57, in run
    result = self.fn(*self.args, **self.kwargs)
  File "/home/bookofscotland/miniconda3/envs/BOS/lib/python3.8/site-packages/asgiref/sync.py", line 538, in thread_handler
    return func(*args, **kwargs)
  File "/var/www/bookscot/public_site/views.py", line 70, in directory_main_view
    directory = get_object_or_404(Directory, id=directory_id)
  File "/home/bookofscotland/miniconda3/envs/BOS/lib/python3.8/site-packages/django/shortcuts.py", line 85, in get_object_or_404
    return queryset.get(*args, **kwargs)
  File "/home/bookofscotland/miniconda3/envs/BOS/lib/python3.8/site-packages/django/db/models/query.py", line 646, in get
    num = len(clone)
  File "/home/bookofscotland/miniconda3/envs/BOS/lib/python3.8/site-packages/django/db/models/query.py", line 376, in __len__
    self._fetch_all()
  File "/home/bookofscotland/miniconda3/envs/BOS/lib/python3.8/site-packages/django/db/models/query.py", line 1866, in _fetch_all
    self._result_cache = list(self._iterable_class(self))
  File "/home/bookofscotland/miniconda3/envs/BOS/lib/python3.8/site-packages/django/db/models/query.py", line 87, in __iter__
    results = compiler.execute_sql(
  File "/home/bookofscotland/miniconda3/envs/BOS/lib/python3.8/site-packages/django/db/models/sql/compiler.py", line 1395, in execute_sql
    cursor.execute(sql, params)
  File "/home/bookofscotland/miniconda3/envs/BOS/lib/python3.8/site-packages/django/db/backends/utils.py", line 67, in execute
    return self._execute_with_wrappers(
  File "/home/bookofscotland/miniconda3/envs/BOS/lib/python3.8/site-packages/django/db/backends/utils.py", line 80, in _execute_with_wrappers
    return executor(sql, params, many, context)
  File "/home/bookofscotland/miniconda3/envs/BOS/lib/python3.8/site-packages/django/db/backends/utils.py", line 89, in _execute
    return self.cursor.execute(sql, params)
  File "/home/bookofscotland/miniconda3/envs/BOS/lib/python3.8/site-packages/django/db/utils.py", line 91, in __exit__
    raise dj_exc_value.with_traceback(traceback) from exc_value
  File "/home/bookofscotland/miniconda3/envs/BOS/lib/python3.8/site-packages/django/db/backends/utils.py", line 89, in _execute
    return self.cursor.execute(sql, params)
  File "/home/bookofscotland/miniconda3/envs/BOS/lib/python3.8/site-packages/django/db/backends/mysql/base.py", line 75, in execute
    return self.cursor.execute(query, args)
  File "/home/bookofscotland/miniconda3/envs/BOS/lib/python3.8/site-packages/MySQLdb/cursors.py", line 179, in execute
    res = self._query(mogrified_query)
  File "/home/bookofscotland/miniconda3/envs/BOS/lib/python3.8/site-packages/MySQLdb/cursors.py", line 330, in _query
    db.query(q)
  File "/home/bookofscotland/miniconda3/envs/BOS/lib/python3.8/site-packages/MySQLdb/connections.py", line 261, in query
    _mysql.connection.query(self, query)
django.db.utils.ProgrammingError: (1146, "Table 'aibos_django.bookscot_site_directory' doesn't exist")
Internal Server Error: /directory/1/
Traceback (most recent call last):
  File "/home/bookofscotland/miniconda3/envs/BOS/lib/python3.8/site-packages/django/db/backends/utils.py", line 89, in _execute
    return self.cursor.execute(sql, params)
  File "/home/bookofscotland/miniconda3/envs/BOS/lib/python3.8/site-packages/django/db/backends/mysql/base.py", line 75, in execute
    return self.cursor.execute(query, args)
  File "/home/bookofscotland/miniconda3/envs/BOS/lib/python3.8/site-packages/MySQLdb/cursors.py", line 179, in execute
    res = self._query(mogrified_query)
  File "/home/bookofscotland/miniconda3/envs/BOS/lib/python3.8/site-packages/MySQLdb/cursors.py", line 330, in _query
    db.query(q)
  File "/home/bookofscotland/miniconda3/envs/BOS/lib/python3.8/site-packages/MySQLdb/connections.py", line 261, in query
    _mysql.connection.query(self, query)
MySQLdb.ProgrammingError: (1146, "Table 'aibos_django.bookscot_site_directory' doesn't exist")

The above exception was the direct cause of the following exception:

Traceback (most recent call last):
  File "/home/bookofscotland/miniconda3/envs/BOS/lib/python3.8/site-packages/asgiref/sync.py", line 534, in thread_handler
    raise exc_info[1]
  File "/home/bookofscotland/miniconda3/envs/BOS/lib/python3.8/site-packages/django/core/handlers/exception.py", line 42, in inner
    response = await get_response(request)
  File "/home/bookofscotland/miniconda3/envs/BOS/lib/python3.8/site-packages/django/core/handlers/base.py", line 253, in _get_response_async
    response = await wrapped_callback(
  File "/home/bookofscotland/miniconda3/envs/BOS/lib/python3.8/site-packages/asgiref/sync.py", line 479, in __call__
    ret: _R = await loop.run_in_executor(
  File "/home/bookofscotland/miniconda3/envs/BOS/lib/python3.8/concurrent/futures/thread.py", line 57, in run
    result = self.fn(*self.args, **self.kwargs)
  File "/home/bookofscotland/miniconda3/envs/BOS/lib/python3.8/site-packages/asgiref/sync.py", line 538, in thread_handler
    return func(*args, **kwargs)
  File "/var/www/bookscot/public_site/views.py", line 70, in directory_main_view
    directory = get_object_or_404(Directory, id=directory_id)
  File "/home/bookofscotland/miniconda3/envs/BOS/lib/python3.8/site-packages/django/shortcuts.py", line 85, in get_object_or_404
    return queryset.get(*args, **kwargs)
  File "/home/bookofscotland/miniconda3/envs/BOS/lib/python3.8/site-packages/django/db/models/query.py", line 646, in get
    num = len(clone)
  File "/home/bookofscotland/miniconda3/envs/BOS/lib/python3.8/site-packages/django/db/models/query.py", line 376, in __len__
    self._fetch_all()
  File "/home/bookofscotland/miniconda3/envs/BOS/lib/python3.8/site-packages/django/db/models/query.py", line 1866, in _fetch_all
    self._result_cache = list(self._iterable_class(self))
  File "/home/bookofscotland/miniconda3/envs/BOS/lib/python3.8/site-packages/django/db/models/query.py", line 87, in __iter__
    results = compiler.execute_sql(
  File "/home/bookofscotland/miniconda3/envs/BOS/lib/python3.8/site-packages/django/db/models/sql/compiler.py", line 1395, in execute_sql
    cursor.execute(sql, params)
  File "/home/bookofscotland/miniconda3/envs/BOS/lib/python3.8/site-packages/django/db/backends/utils.py", line 67, in execute
    return self._execute_with_wrappers(
  File "/home/bookofscotland/miniconda3/envs/BOS/lib/python3.8/site-packages/django/db/backends/utils.py", line 80, in _execute_with_wrappers
    return executor(sql, params, many, context)
  File "/home/bookofscotland/miniconda3/envs/BOS/lib/python3.8/site-packages/django/db/backends/utils.py", line 89, in _execute
    return self.cursor.execute(sql, params)
  File "/home/bookofscotland/miniconda3/envs/BOS/lib/python3.8/site-packages/django/db/utils.py", line 91, in __exit__
    raise dj_exc_value.with_traceback(traceback) from exc_value
  File "/home/bookofscotland/miniconda3/envs/BOS/lib/python3.8/site-packages/django/db/backends/utils.py", line 89, in _execute
    return self.cursor.execute(sql, params)
  File "/home/bookofscotland/miniconda3/envs/BOS/lib/python3.8/site-packages/django/db/backends/mysql/base.py", line 75, in execute
    return self.cursor.execute(query, args)
  File "/home/bookofscotland/miniconda3/envs/BOS/lib/python3.8/site-packages/MySQLdb/cursors.py", line 179, in execute
    res = self._query(mogrified_query)
  File "/home/bookofscotland/miniconda3/envs/BOS/lib/python3.8/site-packages/MySQLdb/cursors.py", line 330, in _query
    db.query(q)
  File "/home/bookofscotland/miniconda3/envs/BOS/lib/python3.8/site-packages/MySQLdb/connections.py", line 261, in query
    _mysql.connection.query(self, query)
django.db.utils.ProgrammingError: (1146, "Table 'aibos_django.bookscot_site_directory' doesn't exist")
Internal Server Error: /directory/2/
Traceback (most recent call last):
  File "/home/bookofscotland/miniconda3/envs/BOS/lib/python3.8/site-packages/django/db/backends/utils.py", line 89, in _execute
    return self.cursor.execute(sql, params)
  File "/home/bookofscotland/miniconda3/envs/BOS/lib/python3.8/site-packages/django/db/backends/mysql/base.py", line 75, in execute
    return self.cursor.execute(query, args)
  File "/home/bookofscotland/miniconda3/envs/BOS/lib/python3.8/site-packages/MySQLdb/cursors.py", line 179, in execute
    res = self._query(mogrified_query)
  File "/home/bookofscotland/miniconda3/envs/BOS/lib/python3.8/site-packages/MySQLdb/cursors.py", line 330, in _query
    db.query(q)
  File "/home/bookofscotland/miniconda3/envs/BOS/lib/python3.8/site-packages/MySQLdb/connections.py", line 261, in query
    _mysql.connection.query(self, query)
MySQLdb.ProgrammingError: (1146, "Table 'aibos_django.bookscot_site_directory' doesn't exist")

The above exception was the direct cause of the following exception:

Traceback (most recent call last):
  File "/home/bookofscotland/miniconda3/envs/BOS/lib/python3.8/site-packages/asgiref/sync.py", line 534, in thread_handler
    raise exc_info[1]
  File "/home/bookofscotland/miniconda3/envs/BOS/lib/python3.8/site-packages/django/core/handlers/exception.py", line 42, in inner
    response = await get_response(request)
  File "/home/bookofscotland/miniconda3/envs/BOS/lib/python3.8/site-packages/django/core/handlers/base.py", line 253, in _get_response_async
    response = await wrapped_callback(
  File "/home/bookofscotland/miniconda3/envs/BOS/lib/python3.8/site-packages/asgiref/sync.py", line 479, in __call__
    ret: _R = await loop.run_in_executor(
  File "/home/bookofscotland/miniconda3/envs/BOS/lib/python3.8/concurrent/futures/thread.py", line 57, in run
    result = self.fn(*self.args, **self.kwargs)
  File "/home/bookofscotland/miniconda3/envs/BOS/lib/python3.8/site-packages/asgiref/sync.py", line 538, in thread_handler
    return func(*args, **kwargs)
  File "/var/www/bookscot/public_site/views.py", line 70, in directory_main_view
    directory = get_object_or_404(Directory, id=directory_id)
  File "/home/bookofscotland/miniconda3/envs/BOS/lib/python3.8/site-packages/django/shortcuts.py", line 85, in get_object_or_404
    return queryset.get(*args, **kwargs)
  File "/home/bookofscotland/miniconda3/envs/BOS/lib/python3.8/site-packages/django/db/models/query.py", line 646, in get
    num = len(clone)
  File "/home/bookofscotland/miniconda3/envs/BOS/lib/python3.8/site-packages/django/db/models/query.py", line 376, in __len__
    self._fetch_all()
  File "/home/bookofscotland/miniconda3/envs/BOS/lib/python3.8/site-packages/django/db/models/query.py", line 1866, in _fetch_all
    self._result_cache = list(self._iterable_class(self))
  File "/home/bookofscotland/miniconda3/envs/BOS/lib/python3.8/site-packages/django/db/models/query.py", line 87, in __iter__
    results = compiler.execute_sql(
  File "/home/bookofscotland/miniconda3/envs/BOS/lib/python3.8/site-packages/django/db/models/sql/compiler.py", line 1395, in execute_sql
    cursor.execute(sql, params)
  File "/home/bookofscotland/miniconda3/envs/BOS/lib/python3.8/site-packages/django/db/backends/utils.py", line 67, in execute
    return self._execute_with_wrappers(
  File "/home/bookofscotland/miniconda3/envs/BOS/lib/python3.8/site-packages/django/db/backends/utils.py", line 80, in _execute_with_wrappers
    return executor(sql, params, many, context)
  File "/home/bookofscotland/miniconda3/envs/BOS/lib/python3.8/site-packages/django/db/backends/utils.py", line 89, in _execute
    return self.cursor.execute(sql, params)
  File "/home/bookofscotland/miniconda3/envs/BOS/lib/python3.8/site-packages/django/db/utils.py", line 91, in __exit__
    raise dj_exc_value.with_traceback(traceback) from exc_value
  File "/home/bookofscotland/miniconda3/envs/BOS/lib/python3.8/site-packages/django/db/backends/utils.py", line 89, in _execute
    return self.cursor.execute(sql, params)
  File "/home/bookofscotland/miniconda3/envs/BOS/lib/python3.8/site-packages/django/db/backends/mysql/base.py", line 75, in execute
    return self.cursor.execute(query, args)
  File "/home/bookofscotland/miniconda3/envs/BOS/lib/python3.8/site-packages/MySQLdb/cursors.py", line 179, in execute
    res = self._query(mogrified_query)
  File "/home/bookofscotland/miniconda3/envs/BOS/lib/python3.8/site-packages/MySQLdb/cursors.py", line 330, in _query
    db.query(q)
  File "/home/bookofscotland/miniconda3/envs/BOS/lib/python3.8/site-packages/MySQLdb/connections.py", line 261, in query
    _mysql.connection.query(self, query)
django.db.utils.ProgrammingError: (1146, "Table 'aibos_django.bookscot_site_directory' doesn't exist")
Internal Server Error: /directory/3/
Traceback (most recent call last):
  File "/home/bookofscotland/miniconda3/envs/BOS/lib/python3.8/site-packages/django/db/backends/utils.py", line 89, in _execute
    return self.cursor.execute(sql, params)
  File "/home/bookofscotland/miniconda3/envs/BOS/lib/python3.8/site-packages/django/db/backends/mysql/base.py", line 75, in execute
    return self.cursor.execute(query, args)
  File "/home/bookofscotland/miniconda3/envs/BOS/lib/python3.8/site-packages/MySQLdb/cursors.py", line 179, in execute
    res = self._query(mogrified_query)
  File "/home/bookofscotland/miniconda3/envs/BOS/lib/python3.8/site-packages/MySQLdb/cursors.py", line 330, in _query
    db.query(q)
  File "/home/bookofscotland/miniconda3/envs/BOS/lib/python3.8/site-packages/MySQLdb/connections.py", line 261, in query
    _mysql.connection.query(self, query)
MySQLdb.ProgrammingError: (1146, "Table 'aibos_django.bookscot_site_directory' doesn't exist")

The above exception was the direct cause of the following exception:

Traceback (most recent call last):
  File "/home/bookofscotland/miniconda3/envs/BOS/lib/python3.8/site-packages/asgiref/sync.py", line 534, in thread_handler
    raise exc_info[1]
  File "/home/bookofscotland/miniconda3/envs/BOS/lib/python3.8/site-packages/django/core/handlers/exception.py", line 42, in inner
    response = await get_response(request)
  File "/home/bookofscotland/miniconda3/envs/BOS/lib/python3.8/site-packages/django/core/handlers/base.py", line 253, in _get_response_async
    response = await wrapped_callback(
  File "/home/bookofscotland/miniconda3/envs/BOS/lib/python3.8/site-packages/asgiref/sync.py", line 479, in __call__
    ret: _R = await loop.run_in_executor(
  File "/home/bookofscotland/miniconda3/envs/BOS/lib/python3.8/concurrent/futures/thread.py", line 57, in run
    result = self.fn(*self.args, **self.kwargs)
  File "/home/bookofscotland/miniconda3/envs/BOS/lib/python3.8/site-packages/asgiref/sync.py", line 538, in thread_handler
    return func(*args, **kwargs)
  File "/var/www/bookscot/public_site/views.py", line 70, in directory_main_view
    directory = get_object_or_404(Directory, id=directory_id)
  File "/home/bookofscotland/miniconda3/envs/BOS/lib/python3.8/site-packages/django/shortcuts.py", line 85, in get_object_or_404
    return queryset.get(*args, **kwargs)
  File "/home/bookofscotland/miniconda3/envs/BOS/lib/python3.8/site-packages/django/db/models/query.py", line 646, in get
    num = len(clone)
  File "/home/bookofscotland/miniconda3/envs/BOS/lib/python3.8/site-packages/django/db/models/query.py", line 376, in __len__
    self._fetch_all()
  File "/home/bookofscotland/miniconda3/envs/BOS/lib/python3.8/site-packages/django/db/models/query.py", line 1866, in _fetch_all
    self._result_cache = list(self._iterable_class(self))
  File "/home/bookofscotland/miniconda3/envs/BOS/lib/python3.8/site-packages/django/db/models/query.py", line 87, in __iter__
    results = compiler.execute_sql(
  File "/home/bookofscotland/miniconda3/envs/BOS/lib/python3.8/site-packages/django/db/models/sql/compiler.py", line 1395, in execute_sql
    cursor.execute(sql, params)
  File "/home/bookofscotland/miniconda3/envs/BOS/lib/python3.8/site-packages/django/db/backends/utils.py", line 67, in execute
    return self._execute_with_wrappers(
  File "/home/bookofscotland/miniconda3/envs/BOS/lib/python3.8/site-packages/django/db/backends/utils.py", line 80, in _execute_with_wrappers
    return executor(sql, params, many, context)
  File "/home/bookofscotland/miniconda3/envs/BOS/lib/python3.8/site-packages/django/db/backends/utils.py", line 89, in _execute
    return self.cursor.execute(sql, params)
  File "/home/bookofscotland/miniconda3/envs/BOS/lib/python3.8/site-packages/django/db/utils.py", line 91, in __exit__
    raise dj_exc_value.with_traceback(traceback) from exc_value
  File "/home/bookofscotland/miniconda3/envs/BOS/lib/python3.8/site-packages/django/db/backends/utils.py", line 89, in _execute
    return self.cursor.execute(sql, params)
  File "/home/bookofscotland/miniconda3/envs/BOS/lib/python3.8/site-packages/django/db/backends/mysql/base.py", line 75, in execute
    return self.cursor.execute(query, args)
  File "/home/bookofscotland/miniconda3/envs/BOS/lib/python3.8/site-packages/MySQLdb/cursors.py", line 179, in execute
    res = self._query(mogrified_query)
  File "/home/bookofscotland/miniconda3/envs/BOS/lib/python3.8/site-packages/MySQLdb/cursors.py", line 330, in _query
    db.query(q)
  File "/home/bookofscotland/miniconda3/envs/BOS/lib/python3.8/site-packages/MySQLdb/connections.py", line 261, in query
    _mysql.connection.query(self, query)
django.db.utils.ProgrammingError: (1146, "Table 'aibos_django.bookscot_site_directory' doesn't exist")
Internal Server Error: /directory/4/
Traceback (most recent call last):
  File "/home/bookofscotland/miniconda3/envs/BOS/lib/python3.8/site-packages/django/db/backends/utils.py", line 89, in _execute
    return self.cursor.execute(sql, params)
  File "/home/bookofscotland/miniconda3/envs/BOS/lib/python3.8/site-packages/django/db/backends/mysql/base.py", line 75, in execute
    return self.cursor.execute(query, args)
  File "/home/bookofscotland/miniconda3/envs/BOS/lib/python3.8/site-packages/MySQLdb/cursors.py", line 179, in execute
    res = self._query(mogrified_query)
  File "/home/bookofscotland/miniconda3/envs/BOS/lib/python3.8/site-packages/MySQLdb/cursors.py", line 330, in _query
    db.query(q)
  File "/home/bookofscotland/miniconda3/envs/BOS/lib/python3.8/site-packages/MySQLdb/connections.py", line 261, in query
    _mysql.connection.query(self, query)
MySQLdb.ProgrammingError: (1146, "Table 'aibos_django.bookscot_site_directory' doesn't exist")

The above exception was the direct cause of the following exception:

Traceback (most recent call last):
  File "/home/bookofscotland/miniconda3/envs/BOS/lib/python3.8/site-packages/asgiref/sync.py", line 534, in thread_handler
    raise exc_info[1]
  File "/home/bookofscotland/miniconda3/envs/BOS/lib/python3.8/site-packages/django/core/handlers/exception.py", line 42, in inner
    response = await get_response(request)
  File "/home/bookofscotland/miniconda3/envs/BOS/lib/python3.8/site-packages/django/core/handlers/base.py", line 253, in _get_response_async
    response = await wrapped_callback(
  File "/home/bookofscotland/miniconda3/envs/BOS/lib/python3.8/site-packages/asgiref/sync.py", line 479, in __call__
    ret: _R = await loop.run_in_executor(
  File "/home/bookofscotland/miniconda3/envs/BOS/lib/python3.8/concurrent/futures/thread.py", line 57, in run
    result = self.fn(*self.args, **self.kwargs)
  File "/home/bookofscotland/miniconda3/envs/BOS/lib/python3.8/site-packages/asgiref/sync.py", line 538, in thread_handler
    return func(*args, **kwargs)
  File "/var/www/bookscot/public_site/views.py", line 70, in directory_main_view
    directory = get_object_or_404(Directory, id=directory_id)
  File "/home/bookofscotland/miniconda3/envs/BOS/lib/python3.8/site-packages/django/shortcuts.py", line 85, in get_object_or_404
    return queryset.get(*args, **kwargs)
  File "/home/bookofscotland/miniconda3/envs/BOS/lib/python3.8/site-packages/django/db/models/query.py", line 646, in get
    num = len(clone)
  File "/home/bookofscotland/miniconda3/envs/BOS/lib/python3.8/site-packages/django/db/models/query.py", line 376, in __len__
    self._fetch_all()
  File "/home/bookofscotland/miniconda3/envs/BOS/lib/python3.8/site-packages/django/db/models/query.py", line 1866, in _fetch_all
    self._result_cache = list(self._iterable_class(self))
  File "/home/bookofscotland/miniconda3/envs/BOS/lib/python3.8/site-packages/django/db/models/query.py", line 87, in __iter__
    results = compiler.execute_sql(
  File "/home/bookofscotland/miniconda3/envs/BOS/lib/python3.8/site-packages/django/db/models/sql/compiler.py", line 1395, in execute_sql
    cursor.execute(sql, params)
  File "/home/bookofscotland/miniconda3/envs/BOS/lib/python3.8/site-packages/django/db/backends/utils.py", line 67, in execute
    return self._execute_with_wrappers(
  File "/home/bookofscotland/miniconda3/envs/BOS/lib/python3.8/site-packages/django/db/backends/utils.py", line 80, in _execute_with_wrappers
    return executor(sql, params, many, context)
  File "/home/bookofscotland/miniconda3/envs/BOS/lib/python3.8/site-packages/django/db/backends/utils.py", line 89, in _execute
    return self.cursor.execute(sql, params)
  File "/home/bookofscotland/miniconda3/envs/BOS/lib/python3.8/site-packages/django/db/utils.py", line 91, in __exit__
    raise dj_exc_value.with_traceback(traceback) from exc_value
  File "/home/bookofscotland/miniconda3/envs/BOS/lib/python3.8/site-packages/django/db/backends/utils.py", line 89, in _execute
    return self.cursor.execute(sql, params)
  File "/home/bookofscotland/miniconda3/envs/BOS/lib/python3.8/site-packages/django/db/backends/mysql/base.py", line 75, in execute
    return self.cursor.execute(query, args)
  File "/home/bookofscotland/miniconda3/envs/BOS/lib/python3.8/site-packages/MySQLdb/cursors.py", line 179, in execute
    res = self._query(mogrified_query)
  File "/home/bookofscotland/miniconda3/envs/BOS/lib/python3.8/site-packages/MySQLdb/cursors.py", line 330, in _query
    db.query(q)
  File "/home/bookofscotland/miniconda3/envs/BOS/lib/python3.8/site-packages/MySQLdb/connections.py", line 261, in query
    _mysql.connection.query(self, query)
django.db.utils.ProgrammingError: (1146, "Table 'aibos_django.bookscot_site_directory' doesn't exist")
Internal Server Error: /directory/3/
Traceback (most recent call last):
  File "/home/bookofscotland/miniconda3/envs/BOS/lib/python3.8/site-packages/django/db/backends/utils.py", line 89, in _execute
    return self.cursor.execute(sql, params)
  File "/home/bookofscotland/miniconda3/envs/BOS/lib/python3.8/site-packages/django/db/backends/mysql/base.py", line 75, in execute
    return self.cursor.execute(query, args)
  File "/home/bookofscotland/miniconda3/envs/BOS/lib/python3.8/site-packages/MySQLdb/cursors.py", line 179, in execute
    res = self._query(mogrified_query)
  File "/home/bookofscotland/miniconda3/envs/BOS/lib/python3.8/site-packages/MySQLdb/cursors.py", line 330, in _query
    db.query(q)
  File "/home/bookofscotland/miniconda3/envs/BOS/lib/python3.8/site-packages/MySQLdb/connections.py", line 261, in query
    _mysql.connection.query(self, query)
MySQLdb.ProgrammingError: (1146, "Table 'aibos_django.bookscot_site_directory' doesn't exist")

The above exception was the direct cause of the following exception:

Traceback (most recent call last):
  File "/home/bookofscotland/miniconda3/envs/BOS/lib/python3.8/site-packages/asgiref/sync.py", line 534, in thread_handler
    raise exc_info[1]
  File "/home/bookofscotland/miniconda3/envs/BOS/lib/python3.8/site-packages/django/core/handlers/exception.py", line 42, in inner
    response = await get_response(request)
  File "/home/bookofscotland/miniconda3/envs/BOS/lib/python3.8/site-packages/django/core/handlers/base.py", line 253, in _get_response_async
    response = await wrapped_callback(
  File "/home/bookofscotland/miniconda3/envs/BOS/lib/python3.8/site-packages/asgiref/sync.py", line 479, in __call__
    ret: _R = await loop.run_in_executor(
  File "/home/bookofscotland/miniconda3/envs/BOS/lib/python3.8/concurrent/futures/thread.py", line 57, in run
    result = self.fn(*self.args, **self.kwargs)
  File "/home/bookofscotland/miniconda3/envs/BOS/lib/python3.8/site-packages/asgiref/sync.py", line 538, in thread_handler
    return func(*args, **kwargs)
  File "/var/www/bookscot/public_site/views.py", line 70, in directory_main_view
    directory = get_object_or_404(Directory, id=directory_id)
  File "/home/bookofscotland/miniconda3/envs/BOS/lib/python3.8/site-packages/django/shortcuts.py", line 85, in get_object_or_404
    return queryset.get(*args, **kwargs)
  File "/home/bookofscotland/miniconda3/envs/BOS/lib/python3.8/site-packages/django/db/models/query.py", line 646, in get
    num = len(clone)
  File "/home/bookofscotland/miniconda3/envs/BOS/lib/python3.8/site-packages/django/db/models/query.py", line 376, in __len__
    self._fetch_all()
  File "/home/bookofscotland/miniconda3/envs/BOS/lib/python3.8/site-packages/django/db/models/query.py", line 1866, in _fetch_all
    self._result_cache = list(self._iterable_class(self))
  File "/home/bookofscotland/miniconda3/envs/BOS/lib/python3.8/site-packages/django/db/models/query.py", line 87, in __iter__
    results = compiler.execute_sql(
  File "/home/bookofscotland/miniconda3/envs/BOS/lib/python3.8/site-packages/django/db/models/sql/compiler.py", line 1395, in execute_sql
    cursor.execute(sql, params)
  File "/home/bookofscotland/miniconda3/envs/BOS/lib/python3.8/site-packages/django/db/backends/utils.py", line 67, in execute
    return self._execute_with_wrappers(
  File "/home/bookofscotland/miniconda3/envs/BOS/lib/python3.8/site-packages/django/db/backends/utils.py", line 80, in _execute_with_wrappers
    return executor(sql, params, many, context)
  File "/home/bookofscotland/miniconda3/envs/BOS/lib/python3.8/site-packages/django/db/backends/utils.py", line 89, in _execute
    return self.cursor.execute(sql, params)
  File "/home/bookofscotland/miniconda3/envs/BOS/lib/python3.8/site-packages/django/db/utils.py", line 91, in __exit__
    raise dj_exc_value.with_traceback(traceback) from exc_value
  File "/home/bookofscotland/miniconda3/envs/BOS/lib/python3.8/site-packages/django/db/backends/utils.py", line 89, in _execute
    return self.cursor.execute(sql, params)
  File "/home/bookofscotland/miniconda3/envs/BOS/lib/python3.8/site-packages/django/db/backends/mysql/base.py", line 75, in execute
    return self.cursor.execute(query, args)
  File "/home/bookofscotland/miniconda3/envs/BOS/lib/python3.8/site-packages/MySQLdb/cursors.py", line 179, in execute
    res = self._query(mogrified_query)
  File "/home/bookofscotland/miniconda3/envs/BOS/lib/python3.8/site-packages/MySQLdb/cursors.py", line 330, in _query
    db.query(q)
  File "/home/bookofscotland/miniconda3/envs/BOS/lib/python3.8/site-packages/MySQLdb/connections.py", line 261, in query
    _mysql.connection.query(self, query)
django.db.utils.ProgrammingError: (1146, "Table 'aibos_django.bookscot_site_directory' doesn't exist")
Internal Server Error: /directory/2/
Traceback (most recent call last):
  File "/home/bookofscotland/miniconda3/envs/BOS/lib/python3.8/site-packages/django/db/backends/utils.py", line 89, in _execute
    return self.cursor.execute(sql, params)
  File "/home/bookofscotland/miniconda3/envs/BOS/lib/python3.8/site-packages/django/db/backends/mysql/base.py", line 75, in execute
    return self.cursor.execute(query, args)
  File "/home/bookofscotland/miniconda3/envs/BOS/lib/python3.8/site-packages/MySQLdb/cursors.py", line 179, in execute
    res = self._query(mogrified_query)
  File "/home/bookofscotland/miniconda3/envs/BOS/lib/python3.8/site-packages/MySQLdb/cursors.py", line 330, in _query
    db.query(q)
  File "/home/bookofscotland/miniconda3/envs/BOS/lib/python3.8/site-packages/MySQLdb/connections.py", line 261, in query
    _mysql.connection.query(self, query)
MySQLdb.ProgrammingError: (1146, "Table 'aibos_django.bookscot_site_directory' doesn't exist")

The above exception was the direct cause of the following exception:

Traceback (most recent call last):
  File "/home/bookofscotland/miniconda3/envs/BOS/lib/python3.8/site-packages/asgiref/sync.py", line 534, in thread_handler
    raise exc_info[1]
  File "/home/bookofscotland/miniconda3/envs/BOS/lib/python3.8/site-packages/django/core/handlers/exception.py", line 42, in inner
    response = await get_response(request)
  File "/home/bookofscotland/miniconda3/envs/BOS/lib/python3.8/site-packages/django/core/handlers/base.py", line 253, in _get_response_async
    response = await wrapped_callback(
  File "/home/bookofscotland/miniconda3/envs/BOS/lib/python3.8/site-packages/asgiref/sync.py", line 479, in __call__
    ret: _R = await loop.run_in_executor(
  File "/home/bookofscotland/miniconda3/envs/BOS/lib/python3.8/concurrent/futures/thread.py", line 57, in run
    result = self.fn(*self.args, **self.kwargs)
  File "/home/bookofscotland/miniconda3/envs/BOS/lib/python3.8/site-packages/asgiref/sync.py", line 538, in thread_handler
    return func(*args, **kwargs)
  File "/var/www/bookscot/public_site/views.py", line 70, in directory_main_view
    directory = get_object_or_404(Directory, id=directory_id)
  File "/home/bookofscotland/miniconda3/envs/BOS/lib/python3.8/site-packages/django/shortcuts.py", line 85, in get_object_or_404
    return queryset.get(*args, **kwargs)
  File "/home/bookofscotland/miniconda3/envs/BOS/lib/python3.8/site-packages/django/db/models/query.py", line 646, in get
    num = len(clone)
  File "/home/bookofscotland/miniconda3/envs/BOS/lib/python3.8/site-packages/django/db/models/query.py", line 376, in __len__
    self._fetch_all()
  File "/home/bookofscotland/miniconda3/envs/BOS/lib/python3.8/site-packages/django/db/models/query.py", line 1866, in _fetch_all
    self._result_cache = list(self._iterable_class(self))
  File "/home/bookofscotland/miniconda3/envs/BOS/lib/python3.8/site-packages/django/db/models/query.py", line 87, in __iter__
    results = compiler.execute_sql(
  File "/home/bookofscotland/miniconda3/envs/BOS/lib/python3.8/site-packages/django/db/models/sql/compiler.py", line 1395, in execute_sql
    cursor.execute(sql, params)
  File "/home/bookofscotland/miniconda3/envs/BOS/lib/python3.8/site-packages/django/db/backends/utils.py", line 67, in execute
    return self._execute_with_wrappers(
  File "/home/bookofscotland/miniconda3/envs/BOS/lib/python3.8/site-packages/django/db/backends/utils.py", line 80, in _execute_with_wrappers
    return executor(sql, params, many, context)
  File "/home/bookofscotland/miniconda3/envs/BOS/lib/python3.8/site-packages/django/db/backends/utils.py", line 89, in _execute
    return self.cursor.execute(sql, params)
  File "/home/bookofscotland/miniconda3/envs/BOS/lib/python3.8/site-packages/django/db/utils.py", line 91, in __exit__
    raise dj_exc_value.with_traceback(traceback) from exc_value
  File "/home/bookofscotland/miniconda3/envs/BOS/lib/python3.8/site-packages/django/db/backends/utils.py", line 89, in _execute
    return self.cursor.execute(sql, params)
  File "/home/bookofscotland/miniconda3/envs/BOS/lib/python3.8/site-packages/django/db/backends/mysql/base.py", line 75, in execute
    return self.cursor.execute(query, args)
  File "/home/bookofscotland/miniconda3/envs/BOS/lib/python3.8/site-packages/MySQLdb/cursors.py", line 179, in execute
    res = self._query(mogrified_query)
  File "/home/bookofscotland/miniconda3/envs/BOS/lib/python3.8/site-packages/MySQLdb/cursors.py", line 330, in _query
    db.query(q)
  File "/home/bookofscotland/miniconda3/envs/BOS/lib/python3.8/site-packages/MySQLdb/connections.py", line 261, in query
    _mysql.connection.query(self, query)
django.db.utils.ProgrammingError: (1146, "Table 'aibos_django.bookscot_site_directory' doesn't exist")
Internal Server Error: /directory/1/
Traceback (most recent call last):
  File "/home/bookofscotland/miniconda3/envs/BOS/lib/python3.8/site-packages/django/db/backends/utils.py", line 89, in _execute
    return self.cursor.execute(sql, params)
  File "/home/bookofscotland/miniconda3/envs/BOS/lib/python3.8/site-packages/django/db/backends/mysql/base.py", line 75, in execute
    return self.cursor.execute(query, args)
  File "/home/bookofscotland/miniconda3/envs/BOS/lib/python3.8/site-packages/MySQLdb/cursors.py", line 179, in execute
    res = self._query(mogrified_query)
  File "/home/bookofscotland/miniconda3/envs/BOS/lib/python3.8/site-packages/MySQLdb/cursors.py", line 330, in _query
    db.query(q)
  File "/home/bookofscotland/miniconda3/envs/BOS/lib/python3.8/site-packages/MySQLdb/connections.py", line 261, in query
    _mysql.connection.query(self, query)
MySQLdb.ProgrammingError: (1146, "Table 'aibos_django.bookscot_site_directory' doesn't exist")

The above exception was the direct cause of the following exception:

Traceback (most recent call last):
  File "/home/bookofscotland/miniconda3/envs/BOS/lib/python3.8/site-packages/asgiref/sync.py", line 534, in thread_handler
    raise exc_info[1]
  File "/home/bookofscotland/miniconda3/envs/BOS/lib/python3.8/site-packages/django/core/handlers/exception.py", line 42, in inner
    response = await get_response(request)
  File "/home/bookofscotland/miniconda3/envs/BOS/lib/python3.8/site-packages/django/core/handlers/base.py", line 253, in _get_response_async
    response = await wrapped_callback(
  File "/home/bookofscotland/miniconda3/envs/BOS/lib/python3.8/site-packages/asgiref/sync.py", line 479, in __call__
    ret: _R = await loop.run_in_executor(
  File "/home/bookofscotland/miniconda3/envs/BOS/lib/python3.8/concurrent/futures/thread.py", line 57, in run
    result = self.fn(*self.args, **self.kwargs)
  File "/home/bookofscotland/miniconda3/envs/BOS/lib/python3.8/site-packages/asgiref/sync.py", line 538, in thread_handler
    return func(*args, **kwargs)
  File "/var/www/bookscot/public_site/views.py", line 70, in directory_main_view
    directory = get_object_or_404(Directory, id=directory_id)
  File "/home/bookofscotland/miniconda3/envs/BOS/lib/python3.8/site-packages/django/shortcuts.py", line 85, in get_object_or_404
    return queryset.get(*args, **kwargs)
  File "/home/bookofscotland/miniconda3/envs/BOS/lib/python3.8/site-packages/django/db/models/query.py", line 646, in get
    num = len(clone)
  File "/home/bookofscotland/miniconda3/envs/BOS/lib/python3.8/site-packages/django/db/models/query.py", line 376, in __len__
    self._fetch_all()
  File "/home/bookofscotland/miniconda3/envs/BOS/lib/python3.8/site-packages/django/db/models/query.py", line 1866, in _fetch_all
    self._result_cache = list(self._iterable_class(self))
  File "/home/bookofscotland/miniconda3/envs/BOS/lib/python3.8/site-packages/django/db/models/query.py", line 87, in __iter__
    results = compiler.execute_sql(
  File "/home/bookofscotland/miniconda3/envs/BOS/lib/python3.8/site-packages/django/db/models/sql/compiler.py", line 1395, in execute_sql
    cursor.execute(sql, params)
  File "/home/bookofscotland/miniconda3/envs/BOS/lib/python3.8/site-packages/django/db/backends/utils.py", line 67, in execute
    return self._execute_with_wrappers(
  File "/home/bookofscotland/miniconda3/envs/BOS/lib/python3.8/site-packages/django/db/backends/utils.py", line 80, in _execute_with_wrappers
    return executor(sql, params, many, context)
  File "/home/bookofscotland/miniconda3/envs/BOS/lib/python3.8/site-packages/django/db/backends/utils.py", line 89, in _execute
    return self.cursor.execute(sql, params)
  File "/home/bookofscotland/miniconda3/envs/BOS/lib/python3.8/site-packages/django/db/utils.py", line 91, in __exit__
    raise dj_exc_value.with_traceback(traceback) from exc_value
  File "/home/bookofscotland/miniconda3/envs/BOS/lib/python3.8/site-packages/django/db/backends/utils.py", line 89, in _execute
    return self.cursor.execute(sql, params)
  File "/home/bookofscotland/miniconda3/envs/BOS/lib/python3.8/site-packages/django/db/backends/mysql/base.py", line 75, in execute
    return self.cursor.execute(query, args)
  File "/home/bookofscotland/miniconda3/envs/BOS/lib/python3.8/site-packages/MySQLdb/cursors.py", line 179, in execute
    res = self._query(mogrified_query)
  File "/home/bookofscotland/miniconda3/envs/BOS/lib/python3.8/site-packages/MySQLdb/cursors.py", line 330, in _query
    db.query(q)
  File "/home/bookofscotland/miniconda3/envs/BOS/lib/python3.8/site-packages/MySQLdb/connections.py", line 261, in query
    _mysql.connection.query(self, query)
django.db.utils.ProgrammingError: (1146, "Table 'aibos_django.bookscot_site_directory' doesn't exist")
Internal Server Error: /directory/4/
Traceback (most recent call last):
  File "/home/bookofscotland/miniconda3/envs/BOS/lib/python3.8/site-packages/django/db/backends/utils.py", line 89, in _execute
    return self.cursor.execute(sql, params)
  File "/home/bookofscotland/miniconda3/envs/BOS/lib/python3.8/site-packages/django/db/backends/mysql/base.py", line 75, in execute
    return self.cursor.execute(query, args)
  File "/home/bookofscotland/miniconda3/envs/BOS/lib/python3.8/site-packages/MySQLdb/cursors.py", line 179, in execute
    res = self._query(mogrified_query)
  File "/home/bookofscotland/miniconda3/envs/BOS/lib/python3.8/site-packages/MySQLdb/cursors.py", line 330, in _query
    db.query(q)
  File "/home/bookofscotland/miniconda3/envs/BOS/lib/python3.8/site-packages/MySQLdb/connections.py", line 261, in query
    _mysql.connection.query(self, query)
MySQLdb.ProgrammingError: (1146, "Table 'aibos_django.bookscot_site_directory' doesn't exist")

The above exception was the direct cause of the following exception:

Traceback (most recent call last):
  File "/home/bookofscotland/miniconda3/envs/BOS/lib/python3.8/site-packages/asgiref/sync.py", line 534, in thread_handler
    raise exc_info[1]
  File "/home/bookofscotland/miniconda3/envs/BOS/lib/python3.8/site-packages/django/core/handlers/exception.py", line 42, in inner
    response = await get_response(request)
  File "/home/bookofscotland/miniconda3/envs/BOS/lib/python3.8/site-packages/django/core/handlers/base.py", line 253, in _get_response_async
    response = await wrapped_callback(
  File "/home/bookofscotland/miniconda3/envs/BOS/lib/python3.8/site-packages/asgiref/sync.py", line 479, in __call__
    ret: _R = await loop.run_in_executor(
  File "/home/bookofscotland/miniconda3/envs/BOS/lib/python3.8/concurrent/futures/thread.py", line 57, in run
    result = self.fn(*self.args, **self.kwargs)
  File "/home/bookofscotland/miniconda3/envs/BOS/lib/python3.8/site-packages/asgiref/sync.py", line 538, in thread_handler
    return func(*args, **kwargs)
  File "/var/www/bookscot/public_site/views.py", line 70, in directory_main_view
    directory = get_object_or_404(Directory, id=directory_id)
  File "/home/bookofscotland/miniconda3/envs/BOS/lib/python3.8/site-packages/django/shortcuts.py", line 85, in get_object_or_404
    return queryset.get(*args, **kwargs)
  File "/home/bookofscotland/miniconda3/envs/BOS/lib/python3.8/site-packages/django/db/models/query.py", line 646, in get
    num = len(clone)
  File "/home/bookofscotland/miniconda3/envs/BOS/lib/python3.8/site-packages/django/db/models/query.py", line 376, in __len__
    self._fetch_all()
  File "/home/bookofscotland/miniconda3/envs/BOS/lib/python3.8/site-packages/django/db/models/query.py", line 1866, in _fetch_all
    self._result_cache = list(self._iterable_class(self))
  File "/home/bookofscotland/miniconda3/envs/BOS/lib/python3.8/site-packages/django/db/models/query.py", line 87, in __iter__
    results = compiler.execute_sql(
  File "/home/bookofscotland/miniconda3/envs/BOS/lib/python3.8/site-packages/django/db/models/sql/compiler.py", line 1395, in execute_sql
    cursor.execute(sql, params)
  File "/home/bookofscotland/miniconda3/envs/BOS/lib/python3.8/site-packages/django/db/backends/utils.py", line 67, in execute
    return self._execute_with_wrappers(
  File "/home/bookofscotland/miniconda3/envs/BOS/lib/python3.8/site-packages/django/db/backends/utils.py", line 80, in _execute_with_wrappers
    return executor(sql, params, many, context)
  File "/home/bookofscotland/miniconda3/envs/BOS/lib/python3.8/site-packages/django/db/backends/utils.py", line 89, in _execute
    return self.cursor.execute(sql, params)
  File "/home/bookofscotland/miniconda3/envs/BOS/lib/python3.8/site-packages/django/db/utils.py", line 91, in __exit__
    raise dj_exc_value.with_traceback(traceback) from exc_value
  File "/home/bookofscotland/miniconda3/envs/BOS/lib/python3.8/site-packages/django/db/backends/utils.py", line 89, in _execute
    return self.cursor.execute(sql, params)
  File "/home/bookofscotland/miniconda3/envs/BOS/lib/python3.8/site-packages/django/db/backends/mysql/base.py", line 75, in execute
    return self.cursor.execute(query, args)
  File "/home/bookofscotland/miniconda3/envs/BOS/lib/python3.8/site-packages/MySQLdb/cursors.py", line 179, in execute
    res = self._query(mogrified_query)
  File "/home/bookofscotland/miniconda3/envs/BOS/lib/python3.8/site-packages/MySQLdb/cursors.py", line 330, in _query
    db.query(q)
  File "/home/bookofscotland/miniconda3/envs/BOS/lib/python3.8/site-packages/MySQLdb/connections.py", line 261, in query
    _mysql.connection.query(self, query)
django.db.utils.ProgrammingError: (1146, "Table 'aibos_django.bookscot_site_directory' doesn't exist")
Internal Server Error: /directory/2/
Traceback (most recent call last):
  File "/home/bookofscotland/miniconda3/envs/BOS/lib/python3.8/site-packages/django/db/backends/utils.py", line 89, in _execute
    return self.cursor.execute(sql, params)
  File "/home/bookofscotland/miniconda3/envs/BOS/lib/python3.8/site-packages/django/db/backends/mysql/base.py", line 75, in execute
    return self.cursor.execute(query, args)
  File "/home/bookofscotland/miniconda3/envs/BOS/lib/python3.8/site-packages/MySQLdb/cursors.py", line 179, in execute
    res = self._query(mogrified_query)
  File "/home/bookofscotland/miniconda3/envs/BOS/lib/python3.8/site-packages/MySQLdb/cursors.py", line 330, in _query
    db.query(q)
  File "/home/bookofscotland/miniconda3/envs/BOS/lib/python3.8/site-packages/MySQLdb/connections.py", line 261, in query
    _mysql.connection.query(self, query)
MySQLdb.ProgrammingError: (1146, "Table 'aibos_django.bookscot_site_directory' doesn't exist")

The above exception was the direct cause of the following exception:

Traceback (most recent call last):
  File "/home/bookofscotland/miniconda3/envs/BOS/lib/python3.8/site-packages/asgiref/sync.py", line 534, in thread_handler
    raise exc_info[1]
  File "/home/bookofscotland/miniconda3/envs/BOS/lib/python3.8/site-packages/django/core/handlers/exception.py", line 42, in inner
    response = await get_response(request)
  File "/home/bookofscotland/miniconda3/envs/BOS/lib/python3.8/site-packages/django/core/handlers/base.py", line 253, in _get_response_async
    response = await wrapped_callback(
  File "/home/bookofscotland/miniconda3/envs/BOS/lib/python3.8/site-packages/asgiref/sync.py", line 479, in __call__
    ret: _R = await loop.run_in_executor(
  File "/home/bookofscotland/miniconda3/envs/BOS/lib/python3.8/concurrent/futures/thread.py", line 57, in run
    result = self.fn(*self.args, **self.kwargs)
  File "/home/bookofscotland/miniconda3/envs/BOS/lib/python3.8/site-packages/asgiref/sync.py", line 538, in thread_handler
    return func(*args, **kwargs)
  File "/var/www/bookscot/public_site/views.py", line 70, in directory_main_view
  File "/home/bookofscotland/miniconda3/envs/BOS/lib/python3.8/site-packages/django/shortcuts.py", line 85, in get_object_or_404
    return queryset.get(*args, **kwargs)
  File "/home/bookofscotland/miniconda3/envs/BOS/lib/python3.8/site-packages/django/db/models/query.py", line 646, in get
    num = len(clone)
  File "/home/bookofscotland/miniconda3/envs/BOS/lib/python3.8/site-packages/django/db/models/query.py", line 376, in __len__
    self._fetch_all()
  File "/home/bookofscotland/miniconda3/envs/BOS/lib/python3.8/site-packages/django/db/models/query.py", line 1866, in _fetch_all
    self._result_cache = list(self._iterable_class(self))
  File "/home/bookofscotland/miniconda3/envs/BOS/lib/python3.8/site-packages/django/db/models/query.py", line 87, in __iter__
    results = compiler.execute_sql(
  File "/home/bookofscotland/miniconda3/envs/BOS/lib/python3.8/site-packages/django/db/models/sql/compiler.py", line 1395, in execute_sql
    cursor.execute(sql, params)
  File "/home/bookofscotland/miniconda3/envs/BOS/lib/python3.8/site-packages/django/db/backends/utils.py", line 67, in execute
    return self._execute_with_wrappers(
  File "/home/bookofscotland/miniconda3/envs/BOS/lib/python3.8/site-packages/django/db/backends/utils.py", line 80, in _execute_with_wrappers
    return executor(sql, params, many, context)
  File "/home/bookofscotland/miniconda3/envs/BOS/lib/python3.8/site-packages/django/db/backends/utils.py", line 89, in _execute
    return self.cursor.execute(sql, params)
  File "/home/bookofscotland/miniconda3/envs/BOS/lib/python3.8/site-packages/django/db/utils.py", line 91, in __exit__
    raise dj_exc_value.with_traceback(traceback) from exc_value
  File "/home/bookofscotland/miniconda3/envs/BOS/lib/python3.8/site-packages/django/db/backends/utils.py", line 89, in _execute
    return self.cursor.execute(sql, params)
  File "/home/bookofscotland/miniconda3/envs/BOS/lib/python3.8/site-packages/django/db/backends/mysql/base.py", line 75, in execute
    return self.cursor.execute(query, args)
  File "/home/bookofscotland/miniconda3/envs/BOS/lib/python3.8/site-packages/MySQLdb/cursors.py", line 179, in execute
    res = self._query(mogrified_query)
  File "/home/bookofscotland/miniconda3/envs/BOS/lib/python3.8/site-packages/MySQLdb/cursors.py", line 330, in _query
    db.query(q)
  File "/home/bookofscotland/miniconda3/envs/BOS/lib/python3.8/site-packages/MySQLdb/connections.py", line 261, in query
    _mysql.connection.query(self, query)
django.db.utils.ProgrammingError: (1146, "Table 'aibos_django.bookscot_site_directory' doesn't exist")
